[2024-09-25T19:58:09.180+0000] {local_task_job_runner.py:120} INFO - ::group::Pre task execution logs
[2024-09-25T19:58:09.206+0000] {taskinstance.py:2073} INFO - Dependencies all met for dep_context=non-requeueable deps ti=<TaskInstance: AirCrashInvestigation_pipeline.scrape_loadS3 manual__2024-09-25T19:54:04.202846+00:00 [queued]>
[2024-09-25T19:58:09.214+0000] {taskinstance.py:2073} INFO - Dependencies all met for dep_context=requeueable deps ti=<TaskInstance: AirCrashInvestigation_pipeline.scrape_loadS3 manual__2024-09-25T19:54:04.202846+00:00 [queued]>
[2024-09-25T19:58:09.214+0000] {taskinstance.py:2303} INFO - Starting attempt 1 of 2
[2024-09-25T19:58:09.221+0000] {taskinstance.py:2327} INFO - Executing <Task(BashOperator): scrape_loadS3> on 2024-09-25 19:54:04.202846+00:00
[2024-09-25T19:58:09.224+0000] {warnings.py:110} WARNING - /home/***/.local/lib/python3.12/site-packages/***/task/task_runner/standard_task_runner.py:61: DeprecationWarning: This process (pid=354) is multi-threaded, use of fork() may lead to deadlocks in the child.
  pid = os.fork()

[2024-09-25T19:58:09.226+0000] {standard_task_runner.py:63} INFO - Started process 356 to run task
[2024-09-25T19:58:09.226+0000] {standard_task_runner.py:90} INFO - Running: ['***', 'tasks', 'run', 'AirCrashInvestigation_pipeline', 'scrape_loadS3', 'manual__2024-09-25T19:54:04.202846+00:00', '--job-id', '12', '--raw', '--subdir', 'DAGS_FOLDER/main_dag.py', '--cfg-path', '/tmp/tmp5qquvfr7']
[2024-09-25T19:58:09.227+0000] {standard_task_runner.py:91} INFO - Job 12: Subtask scrape_loadS3
[2024-09-25T19:58:09.286+0000] {task_command.py:426} INFO - Running <TaskInstance: AirCrashInvestigation_pipeline.scrape_loadS3 manual__2024-09-25T19:54:04.202846+00:00 [running]> on host a5905166bf2e
[2024-09-25T19:58:09.365+0000] {taskinstance.py:2644} INFO - Exporting env vars: AIRFLOW_CTX_DAG_OWNER='***' AIRFLOW_CTX_DAG_ID='AirCrashInvestigation_pipeline' AIRFLOW_CTX_TASK_ID='scrape_loadS3' AIRFLOW_CTX_EXECUTION_DATE='2024-09-25T19:54:04.202846+00:00' AIRFLOW_CTX_TRY_NUMBER='1' AIRFLOW_CTX_DAG_RUN_ID='manual__2024-09-25T19:54:04.202846+00:00'
[2024-09-25T19:58:09.366+0000] {taskinstance.py:430} INFO - ::endgroup::
[2024-09-25T19:58:09.385+0000] {subprocess.py:63} INFO - Tmp dir root location: /tmp
[2024-09-25T19:58:09.386+0000] {subprocess.py:75} INFO - Running command: ['/usr/bin/bash', '-c', 'python3 /opt/***/tasks/flightDataWebScrape.py']
[2024-09-25T19:58:09.394+0000] {subprocess.py:86} INFO - Output:
[2024-09-25T19:59:34.960+0000] {local_task_job_runner.py:310} WARNING - State of this instance has been externally set to None. Terminating instance.
[2024-09-25T19:59:34.962+0000] {local_task_job_runner.py:222} INFO - ::endgroup::
[2024-09-25T19:59:34.964+0000] {process_utils.py:132} INFO - Sending 15 to group 356. PIDs of all processes in the group: [358, 356]
[2024-09-25T19:59:34.965+0000] {process_utils.py:87} INFO - Sending the signal 15 to group 356
[2024-09-25T19:59:34.965+0000] {taskinstance.py:2607} ERROR - Received SIGTERM. Terminating subprocesses.
[2024-09-25T19:59:34.966+0000] {subprocess.py:104} INFO - Sending SIGTERM signal to process group
[2024-09-25T19:59:34.967+0000] {taskinstance.py:441} INFO - ::group::Post task execution logs
[2024-09-25T19:59:34.978+0000] {taskinstance.py:2890} ERROR - Task failed with exception
Traceback (most recent call last):
  File "/home/airflow/.local/lib/python3.12/site-packages/airflow/models/taskinstance.py", line 465, in _execute_task
    result = _execute_callable(context=context, **execute_callable_kwargs)
             ^^^^^^^^^^^^^^^^^^^^^^^^^^^^^^^^^^^^^^^^^^^^^^^^^^^^^^^^^^^^^
  File "/home/airflow/.local/lib/python3.12/site-packages/airflow/models/taskinstance.py", line 432, in _execute_callable
    return execute_callable(context=context, **execute_callable_kwargs)
           ^^^^^^^^^^^^^^^^^^^^^^^^^^^^^^^^^^^^^^^^^^^^^^^^^^^^^^^^^^^^
  File "/home/airflow/.local/lib/python3.12/site-packages/airflow/models/baseoperator.py", line 400, in wrapper
    return func(self, *args, **kwargs)
           ^^^^^^^^^^^^^^^^^^^^^^^^^^^
  File "/home/airflow/.local/lib/python3.12/site-packages/airflow/operators/bash.py", line 234, in execute
    result = self.subprocess_hook.run_command(
             ^^^^^^^^^^^^^^^^^^^^^^^^^^^^^^^^^
  File "/home/airflow/.local/lib/python3.12/site-packages/airflow/hooks/subprocess.py", line 91, in run_command
    for raw_line in iter(self.sub_process.stdout.readline, b""):
  File "/home/airflow/.local/lib/python3.12/site-packages/airflow/models/taskinstance.py", line 2609, in signal_handler
    raise AirflowTaskTerminated("Task received SIGTERM signal")
airflow.exceptions.AirflowTaskTerminated: Task received SIGTERM signal
[2024-09-25T19:59:34.986+0000] {taskinstance.py:1205} INFO - Marking task as FAILED. dag_id=AirCrashInvestigation_pipeline, task_id=scrape_loadS3, execution_date=20240925T195404, start_date=20240925T195809, end_date=20240925T195934
[2024-09-25T19:59:34.998+0000] {standard_task_runner.py:110} ERROR - Failed to execute job 12 for task scrape_loadS3 ((psycopg2.errors.ForeignKeyViolation) insert or update on table "task_fail" violates foreign key constraint "task_fail_ti_fkey"
DETAIL:  Key (dag_id, task_id, run_id, map_index)=(AirCrashInvestigation_pipeline, scrape_loadS3, manual__2024-09-25T19:54:04.202846+00:00, -1) is not present in table "task_instance".

[SQL: INSERT INTO task_fail (task_id, dag_id, run_id, map_index, start_date, end_date, duration) VALUES (%(task_id)s, %(dag_id)s, %(run_id)s, %(map_index)s, %(start_date)s, %(end_date)s, %(duration)s) RETURNING task_fail.id]
[parameters: {'task_id': 'scrape_loadS3', 'dag_id': 'AirCrashInvestigation_pipeline', 'run_id': 'manual__2024-09-25T19:54:04.202846+00:00', 'map_index': -1, 'start_date': datetime.datetime(2024, 9, 25, 19, 58, 9, 206713, tzinfo=Timezone('UTC')), 'end_date': datetime.datetime(2024, 9, 25, 19, 59, 34, 985130, tzinfo=Timezone('UTC')), 'duration': 85}]
(Background on this error at: https://sqlalche.me/e/14/gkpj); 356)
[2024-09-25T19:59:35.024+0000] {process_utils.py:80} INFO - Process psutil.Process(pid=358, status='terminated', started='19:58:08') (358) terminated with exit code None
[2024-09-25T19:59:35.025+0000] {process_utils.py:80} INFO - Process psutil.Process(pid=356, status='terminated', exitcode=1, started='19:58:08') (356) terminated with exit code 1
