[2024-10-02T02:13:43.866+0000] {local_task_job_runner.py:120} INFO - ::group::Pre task execution logs
[2024-10-02T02:13:43.877+0000] {taskinstance.py:2073} INFO - Dependencies all met for dep_context=non-requeueable deps ti=<TaskInstance: AirCrashInvestigation_pipeline.scrape_LoadS3 manual__2024-10-02T02:09:37.160970+00:00 [queued]>
[2024-10-02T02:13:43.880+0000] {taskinstance.py:2073} INFO - Dependencies all met for dep_context=requeueable deps ti=<TaskInstance: AirCrashInvestigation_pipeline.scrape_LoadS3 manual__2024-10-02T02:09:37.160970+00:00 [queued]>
[2024-10-02T02:13:43.880+0000] {taskinstance.py:2303} INFO - Starting attempt 2 of 2
[2024-10-02T02:13:43.886+0000] {taskinstance.py:2327} INFO - Executing <Task(BashOperator): scrape_LoadS3> on 2024-10-02 02:09:37.160970+00:00
[2024-10-02T02:13:43.889+0000] {warnings.py:110} WARNING - /home/***/.local/lib/python3.12/site-packages/***/task/task_runner/standard_task_runner.py:61: DeprecationWarning: This process (pid=156) is multi-threaded, use of fork() may lead to deadlocks in the child.
  pid = os.fork()

[2024-10-02T02:13:43.890+0000] {standard_task_runner.py:63} INFO - Started process 157 to run task
[2024-10-02T02:13:43.890+0000] {standard_task_runner.py:90} INFO - Running: ['***', 'tasks', 'run', 'AirCrashInvestigation_pipeline', 'scrape_LoadS3', 'manual__2024-10-02T02:09:37.160970+00:00', '--job-id', '13', '--raw', '--subdir', 'DAGS_FOLDER/main_dag.py', '--cfg-path', '/tmp/tmpr4b7xnsv']
[2024-10-02T02:13:43.891+0000] {standard_task_runner.py:91} INFO - Job 13: Subtask scrape_LoadS3
[2024-10-02T02:13:43.914+0000] {task_command.py:426} INFO - Running <TaskInstance: AirCrashInvestigation_pipeline.scrape_LoadS3 manual__2024-10-02T02:09:37.160970+00:00 [running]> on host ac8ffcfe4778
[2024-10-02T02:13:43.948+0000] {taskinstance.py:2644} INFO - Exporting env vars: AIRFLOW_CTX_DAG_OWNER='***' AIRFLOW_CTX_DAG_ID='AirCrashInvestigation_pipeline' AIRFLOW_CTX_TASK_ID='scrape_LoadS3' AIRFLOW_CTX_EXECUTION_DATE='2024-10-02T02:09:37.160970+00:00' AIRFLOW_CTX_TRY_NUMBER='2' AIRFLOW_CTX_DAG_RUN_ID='manual__2024-10-02T02:09:37.160970+00:00'
[2024-10-02T02:13:43.949+0000] {taskinstance.py:430} INFO - ::endgroup::
[2024-10-02T02:13:43.955+0000] {subprocess.py:63} INFO - Tmp dir root location: /tmp
[2024-10-02T02:13:43.956+0000] {subprocess.py:75} INFO - Running command: ['/usr/bin/bash', '-c', 'python3 /opt/***/tasks/flightDataWebScrape.py']
[2024-10-02T02:13:43.959+0000] {subprocess.py:86} INFO - Output:
[2024-10-02T02:14:59.414+0000] {subprocess.py:93} INFO - HTTPSConnectionPool(host='www.planecrashinfo.com', port=443): Max retries exceeded with url: /1920/1920.htm (Caused by NewConnectionError('<urllib3.connection.HTTPSConnection object at 0xffffb4cf2db0>: Failed to establish a new connection: [Errno 111] Connection refused'))
[2024-10-02T02:14:59.464+0000] {subprocess.py:97} INFO - Command exited with return code 1
[2024-10-02T02:14:59.464+0000] {taskinstance.py:441} INFO - ::group::Post task execution logs
[2024-10-02T02:14:59.470+0000] {taskinstance.py:2890} ERROR - Task failed with exception
Traceback (most recent call last):
  File "/home/airflow/.local/lib/python3.12/site-packages/airflow/models/taskinstance.py", line 465, in _execute_task
    result = _execute_callable(context=context, **execute_callable_kwargs)
             ^^^^^^^^^^^^^^^^^^^^^^^^^^^^^^^^^^^^^^^^^^^^^^^^^^^^^^^^^^^^^
  File "/home/airflow/.local/lib/python3.12/site-packages/airflow/models/taskinstance.py", line 432, in _execute_callable
    return execute_callable(context=context, **execute_callable_kwargs)
           ^^^^^^^^^^^^^^^^^^^^^^^^^^^^^^^^^^^^^^^^^^^^^^^^^^^^^^^^^^^^
  File "/home/airflow/.local/lib/python3.12/site-packages/airflow/models/baseoperator.py", line 400, in wrapper
    return func(self, *args, **kwargs)
           ^^^^^^^^^^^^^^^^^^^^^^^^^^^
  File "/home/airflow/.local/lib/python3.12/site-packages/airflow/operators/bash.py", line 243, in execute
    raise AirflowException(
airflow.exceptions.AirflowException: Bash command failed. The command returned a non-zero exit code 1.
[2024-10-02T02:14:59.472+0000] {taskinstance.py:1205} INFO - Marking task as FAILED. dag_id=AirCrashInvestigation_pipeline, task_id=scrape_LoadS3, execution_date=20241002T020937, start_date=20241002T021343, end_date=20241002T021459
[2024-10-02T02:14:59.478+0000] {standard_task_runner.py:110} ERROR - Failed to execute job 13 for task scrape_LoadS3 (Bash command failed. The command returned a non-zero exit code 1.; 157)
[2024-10-02T02:14:59.483+0000] {local_task_job_runner.py:240} INFO - Task exited with return code 1
[2024-10-02T02:14:59.493+0000] {taskinstance.py:3482} INFO - 0 downstream tasks scheduled from follow-on schedule check
[2024-10-02T02:14:59.494+0000] {local_task_job_runner.py:222} INFO - ::endgroup::
