[2024-10-02T02:30:27.806+0000] {local_task_job_runner.py:120} INFO - ::group::Pre task execution logs
[2024-10-02T02:30:27.819+0000] {taskinstance.py:2073} INFO - Dependencies all met for dep_context=non-requeueable deps ti=<TaskInstance: AirCrashInvestigation_pipeline.scrape_LoadS3 manual__2024-10-02T02:27:11.058332+00:00 [queued]>
[2024-10-02T02:30:27.824+0000] {taskinstance.py:2073} INFO - Dependencies all met for dep_context=requeueable deps ti=<TaskInstance: AirCrashInvestigation_pipeline.scrape_LoadS3 manual__2024-10-02T02:27:11.058332+00:00 [queued]>
[2024-10-02T02:30:27.825+0000] {taskinstance.py:2303} INFO - Starting attempt 2 of 2
[2024-10-02T02:30:27.832+0000] {taskinstance.py:2327} INFO - Executing <Task(BashOperator): scrape_LoadS3> on 2024-10-02 02:27:11.058332+00:00
[2024-10-02T02:30:27.835+0000] {warnings.py:110} WARNING - /home/***/.local/lib/python3.12/site-packages/***/task/task_runner/standard_task_runner.py:61: DeprecationWarning: This process (pid=412) is multi-threaded, use of fork() may lead to deadlocks in the child.
  pid = os.fork()

[2024-10-02T02:30:27.836+0000] {standard_task_runner.py:63} INFO - Started process 413 to run task
[2024-10-02T02:30:27.836+0000] {standard_task_runner.py:90} INFO - Running: ['***', 'tasks', 'run', 'AirCrashInvestigation_pipeline', 'scrape_LoadS3', 'manual__2024-10-02T02:27:11.058332+00:00', '--job-id', '25', '--raw', '--subdir', 'DAGS_FOLDER/main_dag.py', '--cfg-path', '/tmp/tmp778___3u']
[2024-10-02T02:30:27.837+0000] {standard_task_runner.py:91} INFO - Job 25: Subtask scrape_LoadS3
[2024-10-02T02:30:27.861+0000] {task_command.py:426} INFO - Running <TaskInstance: AirCrashInvestigation_pipeline.scrape_LoadS3 manual__2024-10-02T02:27:11.058332+00:00 [running]> on host ac8ffcfe4778
[2024-10-02T02:30:27.896+0000] {taskinstance.py:2644} INFO - Exporting env vars: AIRFLOW_CTX_DAG_OWNER='***' AIRFLOW_CTX_DAG_ID='AirCrashInvestigation_pipeline' AIRFLOW_CTX_TASK_ID='scrape_LoadS3' AIRFLOW_CTX_EXECUTION_DATE='2024-10-02T02:27:11.058332+00:00' AIRFLOW_CTX_TRY_NUMBER='2' AIRFLOW_CTX_DAG_RUN_ID='manual__2024-10-02T02:27:11.058332+00:00'
[2024-10-02T02:30:27.897+0000] {taskinstance.py:430} INFO - ::endgroup::
[2024-10-02T02:30:27.904+0000] {subprocess.py:63} INFO - Tmp dir root location: /tmp
[2024-10-02T02:30:27.904+0000] {subprocess.py:75} INFO - Running command: ['/usr/bin/bash', '-c', 'python3 /opt/***/tasks/flightDataWebScrape.py']
[2024-10-02T02:30:27.908+0000] {subprocess.py:86} INFO - Output:
[2024-10-02T02:31:43.366+0000] {subprocess.py:93} INFO - HTTPSConnectionPool(host='www.planecrashinfo.com', port=443): Max retries exceeded with url: /1920/1920.htm (Caused by NewConnectionError('<urllib3.connection.HTTPSConnection object at 0xffff7f7f1370>: Failed to establish a new connection: [Errno 111] Connection refused'))
[2024-10-02T02:31:43.415+0000] {subprocess.py:97} INFO - Command exited with return code 1
[2024-10-02T02:31:43.416+0000] {taskinstance.py:441} INFO - ::group::Post task execution logs
[2024-10-02T02:31:43.421+0000] {taskinstance.py:2890} ERROR - Task failed with exception
Traceback (most recent call last):
  File "/home/airflow/.local/lib/python3.12/site-packages/airflow/models/taskinstance.py", line 465, in _execute_task
    result = _execute_callable(context=context, **execute_callable_kwargs)
             ^^^^^^^^^^^^^^^^^^^^^^^^^^^^^^^^^^^^^^^^^^^^^^^^^^^^^^^^^^^^^
  File "/home/airflow/.local/lib/python3.12/site-packages/airflow/models/taskinstance.py", line 432, in _execute_callable
    return execute_callable(context=context, **execute_callable_kwargs)
           ^^^^^^^^^^^^^^^^^^^^^^^^^^^^^^^^^^^^^^^^^^^^^^^^^^^^^^^^^^^^
  File "/home/airflow/.local/lib/python3.12/site-packages/airflow/models/baseoperator.py", line 400, in wrapper
    return func(self, *args, **kwargs)
           ^^^^^^^^^^^^^^^^^^^^^^^^^^^
  File "/home/airflow/.local/lib/python3.12/site-packages/airflow/operators/bash.py", line 243, in execute
    raise AirflowException(
airflow.exceptions.AirflowException: Bash command failed. The command returned a non-zero exit code 1.
[2024-10-02T02:31:43.423+0000] {taskinstance.py:1205} INFO - Marking task as FAILED. dag_id=AirCrashInvestigation_pipeline, task_id=scrape_LoadS3, execution_date=20241002T022711, start_date=20241002T023027, end_date=20241002T023143
[2024-10-02T02:31:43.430+0000] {standard_task_runner.py:110} ERROR - Failed to execute job 25 for task scrape_LoadS3 (Bash command failed. The command returned a non-zero exit code 1.; 413)
[2024-10-02T02:31:43.435+0000] {local_task_job_runner.py:240} INFO - Task exited with return code 1
[2024-10-02T02:31:43.445+0000] {taskinstance.py:3482} INFO - 0 downstream tasks scheduled from follow-on schedule check
[2024-10-02T02:31:43.447+0000] {local_task_job_runner.py:222} INFO - ::endgroup::
