[2024-10-02T00:00:01.070+0000] {local_task_job_runner.py:120} INFO - ::group::Pre task execution logs
[2024-10-02T00:00:01.082+0000] {taskinstance.py:2073} INFO - Dependencies all met for dep_context=non-requeueable deps ti=<TaskInstance: AirCrashInvestigation_pipeline.scrape_LoadS3 scheduled__2024-10-01T00:00:00+00:00 [queued]>
[2024-10-02T00:00:01.086+0000] {taskinstance.py:2073} INFO - Dependencies all met for dep_context=requeueable deps ti=<TaskInstance: AirCrashInvestigation_pipeline.scrape_LoadS3 scheduled__2024-10-01T00:00:00+00:00 [queued]>
[2024-10-02T00:00:01.087+0000] {taskinstance.py:2303} INFO - Starting attempt 1 of 2
[2024-10-02T00:00:01.095+0000] {taskinstance.py:2327} INFO - Executing <Task(BashOperator): scrape_LoadS3> on 2024-10-01 00:00:00+00:00
[2024-10-02T00:00:01.097+0000] {warnings.py:110} WARNING - /home/***/.local/lib/python3.12/site-packages/***/task/task_runner/standard_task_runner.py:61: DeprecationWarning: This process (pid=7681) is multi-threaded, use of fork() may lead to deadlocks in the child.
  pid = os.fork()

[2024-10-02T00:00:01.098+0000] {standard_task_runner.py:63} INFO - Started process 7682 to run task
[2024-10-02T00:00:01.099+0000] {standard_task_runner.py:90} INFO - Running: ['***', 'tasks', 'run', 'AirCrashInvestigation_pipeline', 'scrape_LoadS3', 'scheduled__2024-10-01T00:00:00+00:00', '--job-id', '21', '--raw', '--subdir', 'DAGS_FOLDER/main_dag.py', '--cfg-path', '/tmp/tmp4nc_d_vq']
[2024-10-02T00:00:01.100+0000] {standard_task_runner.py:91} INFO - Job 21: Subtask scrape_LoadS3
[2024-10-02T00:00:01.125+0000] {task_command.py:426} INFO - Running <TaskInstance: AirCrashInvestigation_pipeline.scrape_LoadS3 scheduled__2024-10-01T00:00:00+00:00 [running]> on host 60abf2d32f6d
[2024-10-02T00:00:01.171+0000] {taskinstance.py:2644} INFO - Exporting env vars: AIRFLOW_CTX_DAG_OWNER='***' AIRFLOW_CTX_DAG_ID='AirCrashInvestigation_pipeline' AIRFLOW_CTX_TASK_ID='scrape_LoadS3' AIRFLOW_CTX_EXECUTION_DATE='2024-10-01T00:00:00+00:00' AIRFLOW_CTX_TRY_NUMBER='1' AIRFLOW_CTX_DAG_RUN_ID='scheduled__2024-10-01T00:00:00+00:00'
[2024-10-02T00:00:01.171+0000] {taskinstance.py:430} INFO - ::endgroup::
[2024-10-02T00:00:01.178+0000] {subprocess.py:63} INFO - Tmp dir root location: /tmp
[2024-10-02T00:00:01.179+0000] {subprocess.py:75} INFO - Running command: ['/usr/bin/bash', '-c', 'python3 /opt/***/tasks/flightDataWebScrape.py']
[2024-10-02T00:00:01.183+0000] {subprocess.py:86} INFO - Output:
[2024-10-02T00:02:45.830+0000] {subprocess.py:93} INFO - 1920 fetched
[2024-10-02T00:02:45.833+0000] {subprocess.py:93} INFO - 1921 fetched
[2024-10-02T00:02:45.836+0000] {subprocess.py:93} INFO - 1922 fetched
[2024-10-02T00:02:45.836+0000] {subprocess.py:93} INFO - 1923 fetched
[2024-10-02T00:02:45.836+0000] {subprocess.py:93} INFO - 1924 fetched
[2024-10-02T00:02:45.837+0000] {subprocess.py:93} INFO - 1925 fetched
[2024-10-02T00:02:45.837+0000] {subprocess.py:93} INFO - 1926 fetched
[2024-10-02T00:02:45.837+0000] {subprocess.py:93} INFO - Data saved to S3
[2024-10-02T00:02:45.939+0000] {subprocess.py:97} INFO - Command exited with return code 0
[2024-10-02T00:02:45.940+0000] {taskinstance.py:441} INFO - ::group::Post task execution logs
[2024-10-02T00:02:45.957+0000] {taskinstance.py:1205} INFO - Marking task as SUCCESS. dag_id=AirCrashInvestigation_pipeline, task_id=scrape_LoadS3, execution_date=20241001T000000, start_date=20241002T000001, end_date=20241002T000245
[2024-10-02T00:02:45.987+0000] {local_task_job_runner.py:240} INFO - Task exited with return code 0
[2024-10-02T00:02:45.999+0000] {taskinstance.py:3482} INFO - 1 downstream tasks scheduled from follow-on schedule check
[2024-10-02T00:02:46.000+0000] {local_task_job_runner.py:222} INFO - ::endgroup::
[2024-10-02T00:38:32.205+0000] {local_task_job_runner.py:120} INFO - ::group::Pre task execution logs
[2024-10-02T00:38:32.228+0000] {taskinstance.py:2073} INFO - Dependencies all met for dep_context=non-requeueable deps ti=<TaskInstance: AirCrashInvestigation_pipeline.scrape_LoadS3 scheduled__2024-10-01T00:00:00+00:00 [queued]>
[2024-10-02T00:38:32.240+0000] {taskinstance.py:2073} INFO - Dependencies all met for dep_context=requeueable deps ti=<TaskInstance: AirCrashInvestigation_pipeline.scrape_LoadS3 scheduled__2024-10-01T00:00:00+00:00 [queued]>
[2024-10-02T00:38:32.245+0000] {taskinstance.py:2303} INFO - Starting attempt 1 of 2
[2024-10-02T00:38:32.259+0000] {taskinstance.py:2327} INFO - Executing <Task(BashOperator): scrape_LoadS3> on 2024-10-01 00:00:00+00:00
[2024-10-02T00:38:32.267+0000] {warnings.py:110} WARNING - /home/***/.local/lib/python3.12/site-packages/***/task/task_runner/standard_task_runner.py:61: DeprecationWarning: This process (pid=78) is multi-threaded, use of fork() may lead to deadlocks in the child.
  pid = os.fork()

[2024-10-02T00:38:32.268+0000] {standard_task_runner.py:63} INFO - Started process 89 to run task
[2024-10-02T00:38:32.267+0000] {standard_task_runner.py:90} INFO - Running: ['***', 'tasks', 'run', 'AirCrashInvestigation_pipeline', 'scrape_LoadS3', 'scheduled__2024-10-01T00:00:00+00:00', '--job-id', '10', '--raw', '--subdir', 'DAGS_FOLDER/main_dag.py', '--cfg-path', '/tmp/tmpw6d5p8mk']
[2024-10-02T00:38:32.275+0000] {standard_task_runner.py:91} INFO - Job 10: Subtask scrape_LoadS3
[2024-10-02T00:38:32.338+0000] {task_command.py:426} INFO - Running <TaskInstance: AirCrashInvestigation_pipeline.scrape_LoadS3 scheduled__2024-10-01T00:00:00+00:00 [running]> on host 5050c2f305ab
[2024-10-02T00:38:32.445+0000] {taskinstance.py:2644} INFO - Exporting env vars: AIRFLOW_CTX_DAG_OWNER='***' AIRFLOW_CTX_DAG_ID='AirCrashInvestigation_pipeline' AIRFLOW_CTX_TASK_ID='scrape_LoadS3' AIRFLOW_CTX_EXECUTION_DATE='2024-10-01T00:00:00+00:00' AIRFLOW_CTX_TRY_NUMBER='1' AIRFLOW_CTX_DAG_RUN_ID='scheduled__2024-10-01T00:00:00+00:00'
[2024-10-02T00:38:32.445+0000] {taskinstance.py:430} INFO - ::endgroup::
[2024-10-02T00:38:32.479+0000] {subprocess.py:63} INFO - Tmp dir root location: /tmp
[2024-10-02T00:38:32.485+0000] {subprocess.py:75} INFO - Running command: ['/usr/bin/bash', '-c', 'python3 /opt/***/tasks/flightDataWebScrape.py']
[2024-10-02T00:38:32.498+0000] {subprocess.py:86} INFO - Output:
[2024-10-02T00:38:52.377+0000] {local_task_job_runner.py:310} WARNING - State of this instance has been externally set to failed. Terminating instance.
[2024-10-02T00:38:52.378+0000] {local_task_job_runner.py:222} INFO - ::endgroup::
[2024-10-02T00:38:52.380+0000] {process_utils.py:132} INFO - Sending 15 to group 89. PIDs of all processes in the group: [91, 89]
[2024-10-02T00:38:52.380+0000] {process_utils.py:87} INFO - Sending the signal 15 to group 89
[2024-10-02T00:38:52.380+0000] {taskinstance.py:2607} ERROR - Received SIGTERM. Terminating subprocesses.
[2024-10-02T00:38:52.381+0000] {subprocess.py:104} INFO - Sending SIGTERM signal to process group
[2024-10-02T00:38:52.381+0000] {taskinstance.py:441} INFO - ::group::Post task execution logs
[2024-10-02T00:38:52.399+0000] {process_utils.py:80} INFO - Process psutil.Process(pid=89, status='terminated', exitcode=0, started='00:38:32') (89) terminated with exit code 0
[2024-10-02T00:38:52.400+0000] {process_utils.py:80} INFO - Process psutil.Process(pid=91, status='terminated', started='00:38:32') (91) terminated with exit code None
[2024-10-02T02:09:34.853+0000] {local_task_job_runner.py:120} INFO - ::group::Pre task execution logs
[2024-10-02T02:09:34.888+0000] {taskinstance.py:2073} INFO - Dependencies all met for dep_context=non-requeueable deps ti=<TaskInstance: AirCrashInvestigation_pipeline.scrape_LoadS3 scheduled__2024-10-01T00:00:00+00:00 [queued]>
[2024-10-02T02:09:34.897+0000] {taskinstance.py:2073} INFO - Dependencies all met for dep_context=requeueable deps ti=<TaskInstance: AirCrashInvestigation_pipeline.scrape_LoadS3 scheduled__2024-10-01T00:00:00+00:00 [queued]>
[2024-10-02T02:09:34.898+0000] {taskinstance.py:2303} INFO - Starting attempt 1 of 2
[2024-10-02T02:09:34.915+0000] {taskinstance.py:2327} INFO - Executing <Task(BashOperator): scrape_LoadS3> on 2024-10-01 00:00:00+00:00
[2024-10-02T02:09:34.919+0000] {warnings.py:110} WARNING - /home/***/.local/lib/python3.12/site-packages/***/task/task_runner/standard_task_runner.py:61: DeprecationWarning: This process (pid=87) is multi-threaded, use of fork() may lead to deadlocks in the child.
  pid = os.fork()

[2024-10-02T02:09:34.930+0000] {standard_task_runner.py:63} INFO - Started process 95 to run task
[2024-10-02T02:09:34.927+0000] {standard_task_runner.py:90} INFO - Running: ['***', 'tasks', 'run', 'AirCrashInvestigation_pipeline', 'scrape_LoadS3', 'scheduled__2024-10-01T00:00:00+00:00', '--job-id', '11', '--raw', '--subdir', 'DAGS_FOLDER/main_dag.py', '--cfg-path', '/tmp/tmpm9pe8y2t']
[2024-10-02T02:09:34.937+0000] {standard_task_runner.py:91} INFO - Job 11: Subtask scrape_LoadS3
[2024-10-02T02:09:35.008+0000] {task_command.py:426} INFO - Running <TaskInstance: AirCrashInvestigation_pipeline.scrape_LoadS3 scheduled__2024-10-01T00:00:00+00:00 [running]> on host ac8ffcfe4778
[2024-10-02T02:09:35.108+0000] {taskinstance.py:2644} INFO - Exporting env vars: AIRFLOW_CTX_DAG_OWNER='***' AIRFLOW_CTX_DAG_ID='AirCrashInvestigation_pipeline' AIRFLOW_CTX_TASK_ID='scrape_LoadS3' AIRFLOW_CTX_EXECUTION_DATE='2024-10-01T00:00:00+00:00' AIRFLOW_CTX_TRY_NUMBER='1' AIRFLOW_CTX_DAG_RUN_ID='scheduled__2024-10-01T00:00:00+00:00'
[2024-10-02T02:09:35.109+0000] {taskinstance.py:430} INFO - ::endgroup::
[2024-10-02T02:09:35.127+0000] {subprocess.py:63} INFO - Tmp dir root location: /tmp
[2024-10-02T02:09:35.127+0000] {subprocess.py:75} INFO - Running command: ['/usr/bin/bash', '-c', 'python3 /opt/***/tasks/flightDataWebScrape.py']
[2024-10-02T02:09:35.136+0000] {subprocess.py:86} INFO - Output:
[2024-10-02T02:11:44.124+0000] {subprocess.py:93} INFO - 1920 data accessed
[2024-10-02T02:11:44.125+0000] {subprocess.py:93} INFO - fetched empty data in1920
[2024-10-02T02:11:44.125+0000] {subprocess.py:93} INFO - fetched empty data in1920
[2024-10-02T02:11:44.125+0000] {subprocess.py:93} INFO - fetched empty data in1920
[2024-10-02T02:11:44.125+0000] {subprocess.py:93} INFO - fetched empty data in1920
[2024-10-02T02:11:44.125+0000] {subprocess.py:93} INFO - fetched empty data in1920
[2024-10-02T02:11:44.126+0000] {subprocess.py:93} INFO - fetched empty data in1920
[2024-10-02T02:11:44.126+0000] {subprocess.py:93} INFO - fetched empty data in1920
[2024-10-02T02:11:44.126+0000] {subprocess.py:93} INFO - fetched empty data in1920
[2024-10-02T02:11:44.126+0000] {subprocess.py:93} INFO - fetched empty data in1920
[2024-10-02T02:11:44.126+0000] {subprocess.py:93} INFO - fetched empty data in1920
[2024-10-02T02:11:44.126+0000] {subprocess.py:93} INFO - fetched empty data in1920
[2024-10-02T02:11:44.126+0000] {subprocess.py:93} INFO - fetched empty data in1920
[2024-10-02T02:11:44.127+0000] {subprocess.py:93} INFO - fetched empty data in1920
[2024-10-02T02:11:44.127+0000] {subprocess.py:93} INFO - fetched empty data in1920
[2024-10-02T02:11:44.127+0000] {subprocess.py:93} INFO - fetched empty data in1920
[2024-10-02T02:11:44.127+0000] {subprocess.py:93} INFO - Traceback (most recent call last):
[2024-10-02T02:11:44.127+0000] {subprocess.py:93} INFO -   File "/home/***/.local/lib/python3.12/site-packages/urllib3/connection.py", line 174, in _new_conn
[2024-10-02T02:11:44.127+0000] {subprocess.py:93} INFO -     conn = connection.create_connection(
[2024-10-02T02:11:44.127+0000] {subprocess.py:93} INFO -            ^^^^^^^^^^^^^^^^^^^^^^^^^^^^^
[2024-10-02T02:11:44.128+0000] {subprocess.py:93} INFO -   File "/home/***/.local/lib/python3.12/site-packages/urllib3/util/connection.py", line 95, in create_connection
[2024-10-02T02:11:44.128+0000] {subprocess.py:93} INFO -     raise err
[2024-10-02T02:11:44.128+0000] {subprocess.py:93} INFO -   File "/home/***/.local/lib/python3.12/site-packages/urllib3/util/connection.py", line 85, in create_connection
[2024-10-02T02:11:44.128+0000] {subprocess.py:93} INFO -     sock.connect(sa)
[2024-10-02T02:11:44.128+0000] {subprocess.py:93} INFO - ConnectionRefusedError: [Errno 111] Connection refused
[2024-10-02T02:11:44.128+0000] {subprocess.py:93} INFO - 
[2024-10-02T02:11:44.129+0000] {subprocess.py:93} INFO - During handling of the above exception, another exception occurred:
[2024-10-02T02:11:44.129+0000] {subprocess.py:93} INFO - 
[2024-10-02T02:11:44.129+0000] {subprocess.py:93} INFO - Traceback (most recent call last):
[2024-10-02T02:11:44.129+0000] {subprocess.py:93} INFO -   File "/home/***/.local/lib/python3.12/site-packages/urllib3/connectionpool.py", line 715, in urlopen
[2024-10-02T02:11:44.129+0000] {subprocess.py:93} INFO -     httplib_response = self._make_request(
[2024-10-02T02:11:44.129+0000] {subprocess.py:93} INFO -                        ^^^^^^^^^^^^^^^^^^^
[2024-10-02T02:11:44.129+0000] {subprocess.py:93} INFO -   File "/home/***/.local/lib/python3.12/site-packages/urllib3/connectionpool.py", line 404, in _make_request
[2024-10-02T02:11:44.129+0000] {subprocess.py:93} INFO -     self._validate_conn(conn)
[2024-10-02T02:11:44.130+0000] {subprocess.py:93} INFO -   File "/home/***/.local/lib/python3.12/site-packages/urllib3/connectionpool.py", line 1058, in _validate_conn
[2024-10-02T02:11:44.130+0000] {subprocess.py:93} INFO -     conn.connect()
[2024-10-02T02:11:44.130+0000] {subprocess.py:93} INFO -   File "/home/***/.local/lib/python3.12/site-packages/urllib3/connection.py", line 363, in connect
[2024-10-02T02:11:44.130+0000] {subprocess.py:93} INFO -     self.sock = conn = self._new_conn()
[2024-10-02T02:11:44.130+0000] {subprocess.py:93} INFO -                        ^^^^^^^^^^^^^^^^
[2024-10-02T02:11:44.130+0000] {subprocess.py:93} INFO -   File "/home/***/.local/lib/python3.12/site-packages/urllib3/connection.py", line 186, in _new_conn
[2024-10-02T02:11:44.130+0000] {subprocess.py:93} INFO -     raise NewConnectionError(
[2024-10-02T02:11:44.131+0000] {subprocess.py:93} INFO - urllib3.exceptions.NewConnectionError: <urllib3.connection.HTTPSConnection object at 0xffff7d7bc9b0>: Failed to establish a new connection: [Errno 111] Connection refused
[2024-10-02T02:11:44.131+0000] {subprocess.py:93} INFO - 
[2024-10-02T02:11:44.131+0000] {subprocess.py:93} INFO - During handling of the above exception, another exception occurred:
[2024-10-02T02:11:44.131+0000] {subprocess.py:93} INFO - 
[2024-10-02T02:11:44.131+0000] {subprocess.py:93} INFO - Traceback (most recent call last):
[2024-10-02T02:11:44.131+0000] {subprocess.py:93} INFO -   File "/home/***/.local/lib/python3.12/site-packages/requests/adapters.py", line 486, in send
[2024-10-02T02:11:44.132+0000] {subprocess.py:93} INFO -     resp = conn.urlopen(
[2024-10-02T02:11:44.132+0000] {subprocess.py:93} INFO -            ^^^^^^^^^^^^^
[2024-10-02T02:11:44.132+0000] {subprocess.py:93} INFO -   File "/home/***/.local/lib/python3.12/site-packages/urllib3/connectionpool.py", line 799, in urlopen
[2024-10-02T02:11:44.132+0000] {subprocess.py:93} INFO -     retries = retries.increment(
[2024-10-02T02:11:44.132+0000] {subprocess.py:93} INFO -               ^^^^^^^^^^^^^^^^^^
[2024-10-02T02:11:44.132+0000] {subprocess.py:93} INFO -   File "/home/***/.local/lib/python3.12/site-packages/urllib3/util/retry.py", line 592, in increment
[2024-10-02T02:11:44.132+0000] {subprocess.py:93} INFO -     raise MaxRetryError(_pool, url, error or ResponseError(cause))
[2024-10-02T02:11:44.133+0000] {subprocess.py:93} INFO - urllib3.exceptions.MaxRetryError: HTTPSConnectionPool(host='www.planecrashinfo.com', port=443): Max retries exceeded with url: /1920/1920-25.htm (Caused by NewConnectionError('<urllib3.connection.HTTPSConnection object at 0xffff7d7bc9b0>: Failed to establish a new connection: [Errno 111] Connection refused'))
[2024-10-02T02:11:44.133+0000] {subprocess.py:93} INFO - 
[2024-10-02T02:11:44.133+0000] {subprocess.py:93} INFO - During handling of the above exception, another exception occurred:
[2024-10-02T02:11:44.133+0000] {subprocess.py:93} INFO - 
[2024-10-02T02:11:44.133+0000] {subprocess.py:93} INFO - Traceback (most recent call last):
[2024-10-02T02:11:44.133+0000] {subprocess.py:93} INFO -   File "/opt/***/tasks/flightDataWebScrape.py", line 91, in <module>
[2024-10-02T02:11:44.133+0000] {subprocess.py:93} INFO -     main()
[2024-10-02T02:11:44.133+0000] {subprocess.py:93} INFO -     ^^^^^^
[2024-10-02T02:11:44.134+0000] {subprocess.py:93} INFO -   File "/opt/***/tasks/flightDataWebScrape.py", line 37, in main
[2024-10-02T02:11:44.134+0000] {subprocess.py:93} INFO -     r = requests.get(url + str(year) + s + end2)
[2024-10-02T02:11:44.134+0000] {subprocess.py:93} INFO -         ^^^^^^^^^^^^^^^^^^^^^^^^^^^^^^^^^^^^^^^^
[2024-10-02T02:11:44.134+0000] {subprocess.py:93} INFO -   File "/home/***/.local/lib/python3.12/site-packages/requests/api.py", line 73, in get
[2024-10-02T02:11:44.134+0000] {subprocess.py:93} INFO -     return request("get", url, params=params, **kwargs)
[2024-10-02T02:11:44.134+0000] {subprocess.py:93} INFO -            ^^^^^^^^^^^^^^^^^^^^^^^^^^^^^^^^^^^^^^^^^^^^
[2024-10-02T02:11:44.134+0000] {subprocess.py:93} INFO -   File "/home/***/.local/lib/python3.12/site-packages/requests/api.py", line 59, in request
[2024-10-02T02:11:44.135+0000] {subprocess.py:93} INFO -     return session.request(method=method, url=url, **kwargs)
[2024-10-02T02:11:44.135+0000] {subprocess.py:93} INFO -            ^^^^^^^^^^^^^^^^^^^^^^^^^^^^^^^^^^^^^^^^^^^^^^^^^
[2024-10-02T02:11:44.135+0000] {subprocess.py:93} INFO -   File "/home/***/.local/lib/python3.12/site-packages/requests/sessions.py", line 589, in request
[2024-10-02T02:11:44.135+0000] {subprocess.py:93} INFO -     resp = self.send(prep, **send_kwargs)
[2024-10-02T02:11:44.135+0000] {subprocess.py:93} INFO -            ^^^^^^^^^^^^^^^^^^^^^^^^^^^^^^
[2024-10-02T02:11:44.135+0000] {subprocess.py:93} INFO -   File "/home/***/.local/lib/python3.12/site-packages/requests/sessions.py", line 703, in send
[2024-10-02T02:11:44.135+0000] {subprocess.py:93} INFO -     r = adapter.send(request, **kwargs)
[2024-10-02T02:11:44.136+0000] {subprocess.py:93} INFO -         ^^^^^^^^^^^^^^^^^^^^^^^^^^^^^^^
[2024-10-02T02:11:44.136+0000] {subprocess.py:93} INFO -   File "/home/***/.local/lib/python3.12/site-packages/requests/adapters.py", line 519, in send
[2024-10-02T02:11:44.137+0000] {subprocess.py:93} INFO -     raise ConnectionError(e, request=request)
[2024-10-02T02:11:44.137+0000] {subprocess.py:93} INFO - requests.exceptions.ConnectionError: HTTPSConnectionPool(host='www.planecrashinfo.com', port=443): Max retries exceeded with url: /1920/1920-25.htm (Caused by NewConnectionError('<urllib3.connection.HTTPSConnection object at 0xffff7d7bc9b0>: Failed to establish a new connection: [Errno 111] Connection refused'))
[2024-10-02T02:11:44.170+0000] {subprocess.py:97} INFO - Command exited with return code 1
[2024-10-02T02:11:44.171+0000] {taskinstance.py:441} INFO - ::group::Post task execution logs
[2024-10-02T02:11:44.177+0000] {taskinstance.py:2890} ERROR - Task failed with exception
Traceback (most recent call last):
  File "/home/airflow/.local/lib/python3.12/site-packages/airflow/models/taskinstance.py", line 465, in _execute_task
    result = _execute_callable(context=context, **execute_callable_kwargs)
             ^^^^^^^^^^^^^^^^^^^^^^^^^^^^^^^^^^^^^^^^^^^^^^^^^^^^^^^^^^^^^
  File "/home/airflow/.local/lib/python3.12/site-packages/airflow/models/taskinstance.py", line 432, in _execute_callable
    return execute_callable(context=context, **execute_callable_kwargs)
           ^^^^^^^^^^^^^^^^^^^^^^^^^^^^^^^^^^^^^^^^^^^^^^^^^^^^^^^^^^^^
  File "/home/airflow/.local/lib/python3.12/site-packages/airflow/models/baseoperator.py", line 400, in wrapper
    return func(self, *args, **kwargs)
           ^^^^^^^^^^^^^^^^^^^^^^^^^^^
  File "/home/airflow/.local/lib/python3.12/site-packages/airflow/operators/bash.py", line 243, in execute
    raise AirflowException(
airflow.exceptions.AirflowException: Bash command failed. The command returned a non-zero exit code 1.
[2024-10-02T02:11:44.179+0000] {taskinstance.py:1205} INFO - Marking task as UP_FOR_RETRY. dag_id=AirCrashInvestigation_pipeline, task_id=scrape_LoadS3, execution_date=20241001T000000, start_date=20241002T020934, end_date=20241002T021144
[2024-10-02T02:11:44.186+0000] {standard_task_runner.py:110} ERROR - Failed to execute job 11 for task scrape_LoadS3 (Bash command failed. The command returned a non-zero exit code 1.; 95)
[2024-10-02T02:11:44.199+0000] {local_task_job_runner.py:240} INFO - Task exited with return code 1
[2024-10-02T02:11:44.212+0000] {taskinstance.py:3482} INFO - 0 downstream tasks scheduled from follow-on schedule check
[2024-10-02T02:11:44.213+0000] {local_task_job_runner.py:222} INFO - ::endgroup::
