[2024-09-25T21:33:00.057+0000] {local_task_job_runner.py:123} INFO - ::group::Pre task execution logs
[2024-09-25T21:33:00.130+0000] {taskinstance.py:2612} INFO - Dependencies all met for dep_context=non-requeueable deps ti=<TaskInstance: AirCrashInvestigation_pipeline.scrape_LoadS3 scheduled__2024-09-23T00:00:00+00:00 [queued]>
[2024-09-25T21:33:00.160+0000] {taskinstance.py:2612} INFO - Dependencies all met for dep_context=requeueable deps ti=<TaskInstance: AirCrashInvestigation_pipeline.scrape_LoadS3 scheduled__2024-09-23T00:00:00+00:00 [queued]>
[2024-09-25T21:33:00.165+0000] {taskinstance.py:2865} INFO - Starting attempt 1 of 2
[2024-09-25T21:33:00.216+0000] {taskinstance.py:2888} INFO - Executing <Task(BashOperator): scrape_LoadS3> on 2024-09-23 00:00:00+00:00
[2024-09-25T21:33:00.230+0000] {standard_task_runner.py:104} INFO - Running: ['***', 'tasks', 'run', 'AirCrashInvestigation_pipeline', 'scrape_LoadS3', 'scheduled__2024-09-23T00:00:00+00:00', '--job-id', '3', '--raw', '--subdir', 'DAGS_FOLDER/main_dag.py', '--cfg-path', '/tmp/tmpkb4axa34']
[2024-09-25T21:33:00.242+0000] {standard_task_runner.py:105} INFO - Job 3: Subtask scrape_LoadS3
[2024-09-25T21:33:00.307+0000] {logging_mixin.py:190} WARNING - /home/***/.local/lib/python3.12/site-packages/***/task/task_runner/standard_task_runner.py:70 DeprecationWarning: This process (pid=189) is multi-threaded, use of fork() may lead to deadlocks in the child.
[2024-09-25T21:33:00.318+0000] {standard_task_runner.py:72} INFO - Started process 195 to run task
[2024-09-25T21:33:00.385+0000] {task_command.py:467} INFO - Running <TaskInstance: AirCrashInvestigation_pipeline.scrape_LoadS3 scheduled__2024-09-23T00:00:00+00:00 [running]> on host fa5d07744004
[2024-09-25T21:33:00.680+0000] {taskinstance.py:3131} INFO - Exporting env vars: AIRFLOW_CTX_DAG_OWNER='***' AIRFLOW_CTX_DAG_ID='AirCrashInvestigation_pipeline' AIRFLOW_CTX_TASK_ID='scrape_LoadS3' AIRFLOW_CTX_EXECUTION_DATE='2024-09-23T00:00:00+00:00' AIRFLOW_CTX_TRY_NUMBER='1' AIRFLOW_CTX_DAG_RUN_ID='scheduled__2024-09-23T00:00:00+00:00'
[2024-09-25T21:33:00.687+0000] {taskinstance.py:731} INFO - ::endgroup::
[2024-09-25T21:33:00.788+0000] {subprocess.py:63} INFO - Tmp dir root location: /tmp
[2024-09-25T21:33:00.791+0000] {subprocess.py:75} INFO - Running command: ['/usr/bin/bash', '-c', 'python3 opt/***/tasks/flightDataWebScrape.py']
[2024-09-25T21:33:00.809+0000] {subprocess.py:86} INFO - Output:
[2024-09-25T21:33:00.978+0000] {subprocess.py:93} INFO - python3: can't open file '/tmp/***tmpn7v5p1pw/opt/***/tasks/flightDataWebScrape.py': [Errno 2] No such file or directory
[2024-09-25T21:33:00.988+0000] {subprocess.py:97} INFO - Command exited with return code 2
[2024-09-25T21:33:01.019+0000] {taskinstance.py:3310} ERROR - Task failed with exception
Traceback (most recent call last):
  File "/home/airflow/.local/lib/python3.12/site-packages/airflow/models/taskinstance.py", line 767, in _execute_task
    result = _execute_callable(context=context, **execute_callable_kwargs)
             ^^^^^^^^^^^^^^^^^^^^^^^^^^^^^^^^^^^^^^^^^^^^^^^^^^^^^^^^^^^^^
  File "/home/airflow/.local/lib/python3.12/site-packages/airflow/models/taskinstance.py", line 733, in _execute_callable
    return ExecutionCallableRunner(
           ^^^^^^^^^^^^^^^^^^^^^^^^
  File "/home/airflow/.local/lib/python3.12/site-packages/airflow/utils/operator_helpers.py", line 252, in run
    return self.func(*args, **kwargs)
           ^^^^^^^^^^^^^^^^^^^^^^^^^^
  File "/home/airflow/.local/lib/python3.12/site-packages/airflow/models/baseoperator.py", line 406, in wrapper
    return func(self, *args, **kwargs)
           ^^^^^^^^^^^^^^^^^^^^^^^^^^^
  File "/home/airflow/.local/lib/python3.12/site-packages/airflow/operators/bash.py", line 249, in execute
    raise AirflowException(
airflow.exceptions.AirflowException: Bash command failed. The command returned a non-zero exit code 2.
[2024-09-25T21:33:01.045+0000] {taskinstance.py:1225} INFO - Marking task as UP_FOR_RETRY. dag_id=AirCrashInvestigation_pipeline, task_id=scrape_LoadS3, run_id=scheduled__2024-09-23T00:00:00+00:00, execution_date=20240923T000000, start_date=20240925T213300, end_date=20240925T213301
[2024-09-25T21:33:01.087+0000] {taskinstance.py:340} INFO - ::group::Post task execution logs
[2024-09-25T21:33:01.095+0000] {standard_task_runner.py:124} ERROR - Failed to execute job 3 for task scrape_LoadS3 (Bash command failed. The command returned a non-zero exit code 2.; 195)
Traceback (most recent call last):
  File "/home/airflow/.local/lib/python3.12/site-packages/airflow/task/task_runner/standard_task_runner.py", line 117, in _start_by_fork
    ret = args.func(args, dag=self.dag)
          ^^^^^^^^^^^^^^^^^^^^^^^^^^^^^
  File "/home/airflow/.local/lib/python3.12/site-packages/airflow/cli/cli_config.py", line 49, in command
    return func(*args, **kwargs)
           ^^^^^^^^^^^^^^^^^^^^^
  File "/home/airflow/.local/lib/python3.12/site-packages/airflow/utils/cli.py", line 115, in wrapper
    return f(*args, **kwargs)
           ^^^^^^^^^^^^^^^^^^
  File "/home/airflow/.local/lib/python3.12/site-packages/airflow/cli/commands/task_command.py", line 483, in task_run
    task_return_code = _run_task_by_selected_method(args, _dag, ti)
                       ^^^^^^^^^^^^^^^^^^^^^^^^^^^^^^^^^^^^^^^^^^^^
  File "/home/airflow/.local/lib/python3.12/site-packages/airflow/cli/commands/task_command.py", line 256, in _run_task_by_selected_method
    return _run_raw_task(args, ti)
           ^^^^^^^^^^^^^^^^^^^^^^^
  File "/home/airflow/.local/lib/python3.12/site-packages/airflow/cli/commands/task_command.py", line 341, in _run_raw_task
    return ti._run_raw_task(
           ^^^^^^^^^^^^^^^^^
  File "/home/airflow/.local/lib/python3.12/site-packages/airflow/utils/session.py", line 97, in wrapper
    return func(*args, session=session, **kwargs)
           ^^^^^^^^^^^^^^^^^^^^^^^^^^^^^^^^^^^^^^
  File "/home/airflow/.local/lib/python3.12/site-packages/airflow/models/taskinstance.py", line 3004, in _run_raw_task
    return _run_raw_task(
           ^^^^^^^^^^^^^^
  File "/home/airflow/.local/lib/python3.12/site-packages/airflow/models/taskinstance.py", line 273, in _run_raw_task
    TaskInstance._execute_task_with_callbacks(
  File "/home/airflow/.local/lib/python3.12/site-packages/airflow/models/taskinstance.py", line 3158, in _execute_task_with_callbacks
    result = self._execute_task(context, task_orig)
             ^^^^^^^^^^^^^^^^^^^^^^^^^^^^^^^^^^^^^^
  File "/home/airflow/.local/lib/python3.12/site-packages/airflow/models/taskinstance.py", line 3182, in _execute_task
    return _execute_task(self, context, task_orig)
           ^^^^^^^^^^^^^^^^^^^^^^^^^^^^^^^^^^^^^^^
  File "/home/airflow/.local/lib/python3.12/site-packages/airflow/models/taskinstance.py", line 767, in _execute_task
    result = _execute_callable(context=context, **execute_callable_kwargs)
             ^^^^^^^^^^^^^^^^^^^^^^^^^^^^^^^^^^^^^^^^^^^^^^^^^^^^^^^^^^^^^
  File "/home/airflow/.local/lib/python3.12/site-packages/airflow/models/taskinstance.py", line 733, in _execute_callable
    return ExecutionCallableRunner(
           ^^^^^^^^^^^^^^^^^^^^^^^^
  File "/home/airflow/.local/lib/python3.12/site-packages/airflow/utils/operator_helpers.py", line 252, in run
    return self.func(*args, **kwargs)
           ^^^^^^^^^^^^^^^^^^^^^^^^^^
  File "/home/airflow/.local/lib/python3.12/site-packages/airflow/models/baseoperator.py", line 406, in wrapper
    return func(self, *args, **kwargs)
           ^^^^^^^^^^^^^^^^^^^^^^^^^^^
  File "/home/airflow/.local/lib/python3.12/site-packages/airflow/operators/bash.py", line 249, in execute
    raise AirflowException(
airflow.exceptions.AirflowException: Bash command failed. The command returned a non-zero exit code 2.
[2024-09-25T21:33:01.140+0000] {local_task_job_runner.py:266} INFO - Task exited with return code 1
[2024-09-25T21:33:01.204+0000] {taskinstance.py:3900} INFO - 0 downstream tasks scheduled from follow-on schedule check
[2024-09-25T21:33:01.216+0000] {local_task_job_runner.py:245} INFO - ::endgroup::
[2024-09-25T21:39:02.995+0000] {local_task_job_runner.py:123} INFO - ::group::Pre task execution logs
[2024-09-25T21:39:03.006+0000] {taskinstance.py:2612} INFO - Dependencies all met for dep_context=non-requeueable deps ti=<TaskInstance: AirCrashInvestigation_pipeline.scrape_LoadS3 scheduled__2024-09-23T00:00:00+00:00 [queued]>
[2024-09-25T21:39:03.012+0000] {taskinstance.py:2612} INFO - Dependencies all met for dep_context=requeueable deps ti=<TaskInstance: AirCrashInvestigation_pipeline.scrape_LoadS3 scheduled__2024-09-23T00:00:00+00:00 [queued]>
[2024-09-25T21:39:03.013+0000] {taskinstance.py:2865} INFO - Starting attempt 1 of 2
[2024-09-25T21:39:03.021+0000] {taskinstance.py:2888} INFO - Executing <Task(BashOperator): scrape_LoadS3> on 2024-09-23 00:00:00+00:00
[2024-09-25T21:39:03.026+0000] {standard_task_runner.py:104} INFO - Running: ['***', 'tasks', 'run', 'AirCrashInvestigation_pipeline', 'scrape_LoadS3', 'scheduled__2024-09-23T00:00:00+00:00', '--job-id', '22', '--raw', '--subdir', 'DAGS_FOLDER/main_dag.py', '--cfg-path', '/tmp/tmpj_f9f1r2']
[2024-09-25T21:39:03.028+0000] {standard_task_runner.py:105} INFO - Job 22: Subtask scrape_LoadS3
[2024-09-25T21:39:03.032+0000] {logging_mixin.py:190} WARNING - /home/***/.local/lib/python3.12/site-packages/***/task/task_runner/standard_task_runner.py:70 DeprecationWarning: This process (pid=405) is multi-threaded, use of fork() may lead to deadlocks in the child.
[2024-09-25T21:39:03.034+0000] {standard_task_runner.py:72} INFO - Started process 407 to run task
[2024-09-25T21:39:03.066+0000] {task_command.py:467} INFO - Running <TaskInstance: AirCrashInvestigation_pipeline.scrape_LoadS3 scheduled__2024-09-23T00:00:00+00:00 [running]> on host fa5d07744004
[2024-09-25T21:39:03.107+0000] {taskinstance.py:3131} INFO - Exporting env vars: AIRFLOW_CTX_DAG_OWNER='***' AIRFLOW_CTX_DAG_ID='AirCrashInvestigation_pipeline' AIRFLOW_CTX_TASK_ID='scrape_LoadS3' AIRFLOW_CTX_EXECUTION_DATE='2024-09-23T00:00:00+00:00' AIRFLOW_CTX_TRY_NUMBER='1' AIRFLOW_CTX_DAG_RUN_ID='scheduled__2024-09-23T00:00:00+00:00'
[2024-09-25T21:39:03.108+0000] {taskinstance.py:731} INFO - ::endgroup::
[2024-09-25T21:39:03.116+0000] {subprocess.py:63} INFO - Tmp dir root location: /tmp
[2024-09-25T21:39:03.117+0000] {subprocess.py:75} INFO - Running command: ['/usr/bin/bash', '-c', 'python3 ./opt/***/tasks/flightDataWebScrape.py']
[2024-09-25T21:39:03.123+0000] {subprocess.py:86} INFO - Output:
[2024-09-25T21:39:03.146+0000] {subprocess.py:93} INFO - python3: can't open file '/tmp/***tmpkeokbp4y/./opt/***/tasks/flightDataWebScrape.py': [Errno 2] No such file or directory
[2024-09-25T21:39:03.150+0000] {subprocess.py:97} INFO - Command exited with return code 2
[2024-09-25T21:39:03.162+0000] {taskinstance.py:3310} ERROR - Task failed with exception
Traceback (most recent call last):
  File "/home/airflow/.local/lib/python3.12/site-packages/airflow/models/taskinstance.py", line 767, in _execute_task
    result = _execute_callable(context=context, **execute_callable_kwargs)
             ^^^^^^^^^^^^^^^^^^^^^^^^^^^^^^^^^^^^^^^^^^^^^^^^^^^^^^^^^^^^^
  File "/home/airflow/.local/lib/python3.12/site-packages/airflow/models/taskinstance.py", line 733, in _execute_callable
    return ExecutionCallableRunner(
           ^^^^^^^^^^^^^^^^^^^^^^^^
  File "/home/airflow/.local/lib/python3.12/site-packages/airflow/utils/operator_helpers.py", line 252, in run
    return self.func(*args, **kwargs)
           ^^^^^^^^^^^^^^^^^^^^^^^^^^
  File "/home/airflow/.local/lib/python3.12/site-packages/airflow/models/baseoperator.py", line 406, in wrapper
    return func(self, *args, **kwargs)
           ^^^^^^^^^^^^^^^^^^^^^^^^^^^
  File "/home/airflow/.local/lib/python3.12/site-packages/airflow/operators/bash.py", line 249, in execute
    raise AirflowException(
airflow.exceptions.AirflowException: Bash command failed. The command returned a non-zero exit code 2.
[2024-09-25T21:39:03.170+0000] {taskinstance.py:1225} INFO - Marking task as UP_FOR_RETRY. dag_id=AirCrashInvestigation_pipeline, task_id=scrape_LoadS3, run_id=scheduled__2024-09-23T00:00:00+00:00, execution_date=20240923T000000, start_date=20240925T213903, end_date=20240925T213903
[2024-09-25T21:39:03.181+0000] {taskinstance.py:340} INFO - ::group::Post task execution logs
[2024-09-25T21:39:03.183+0000] {standard_task_runner.py:124} ERROR - Failed to execute job 22 for task scrape_LoadS3 (Bash command failed. The command returned a non-zero exit code 2.; 407)
Traceback (most recent call last):
  File "/home/airflow/.local/lib/python3.12/site-packages/airflow/task/task_runner/standard_task_runner.py", line 117, in _start_by_fork
    ret = args.func(args, dag=self.dag)
          ^^^^^^^^^^^^^^^^^^^^^^^^^^^^^
  File "/home/airflow/.local/lib/python3.12/site-packages/airflow/cli/cli_config.py", line 49, in command
    return func(*args, **kwargs)
           ^^^^^^^^^^^^^^^^^^^^^
  File "/home/airflow/.local/lib/python3.12/site-packages/airflow/utils/cli.py", line 115, in wrapper
    return f(*args, **kwargs)
           ^^^^^^^^^^^^^^^^^^
  File "/home/airflow/.local/lib/python3.12/site-packages/airflow/cli/commands/task_command.py", line 483, in task_run
    task_return_code = _run_task_by_selected_method(args, _dag, ti)
                       ^^^^^^^^^^^^^^^^^^^^^^^^^^^^^^^^^^^^^^^^^^^^
  File "/home/airflow/.local/lib/python3.12/site-packages/airflow/cli/commands/task_command.py", line 256, in _run_task_by_selected_method
    return _run_raw_task(args, ti)
           ^^^^^^^^^^^^^^^^^^^^^^^
  File "/home/airflow/.local/lib/python3.12/site-packages/airflow/cli/commands/task_command.py", line 341, in _run_raw_task
    return ti._run_raw_task(
           ^^^^^^^^^^^^^^^^^
  File "/home/airflow/.local/lib/python3.12/site-packages/airflow/utils/session.py", line 97, in wrapper
    return func(*args, session=session, **kwargs)
           ^^^^^^^^^^^^^^^^^^^^^^^^^^^^^^^^^^^^^^
  File "/home/airflow/.local/lib/python3.12/site-packages/airflow/models/taskinstance.py", line 3004, in _run_raw_task
    return _run_raw_task(
           ^^^^^^^^^^^^^^
  File "/home/airflow/.local/lib/python3.12/site-packages/airflow/models/taskinstance.py", line 273, in _run_raw_task
    TaskInstance._execute_task_with_callbacks(
  File "/home/airflow/.local/lib/python3.12/site-packages/airflow/models/taskinstance.py", line 3158, in _execute_task_with_callbacks
    result = self._execute_task(context, task_orig)
             ^^^^^^^^^^^^^^^^^^^^^^^^^^^^^^^^^^^^^^
  File "/home/airflow/.local/lib/python3.12/site-packages/airflow/models/taskinstance.py", line 3182, in _execute_task
    return _execute_task(self, context, task_orig)
           ^^^^^^^^^^^^^^^^^^^^^^^^^^^^^^^^^^^^^^^
  File "/home/airflow/.local/lib/python3.12/site-packages/airflow/models/taskinstance.py", line 767, in _execute_task
    result = _execute_callable(context=context, **execute_callable_kwargs)
             ^^^^^^^^^^^^^^^^^^^^^^^^^^^^^^^^^^^^^^^^^^^^^^^^^^^^^^^^^^^^^
  File "/home/airflow/.local/lib/python3.12/site-packages/airflow/models/taskinstance.py", line 733, in _execute_callable
    return ExecutionCallableRunner(
           ^^^^^^^^^^^^^^^^^^^^^^^^
  File "/home/airflow/.local/lib/python3.12/site-packages/airflow/utils/operator_helpers.py", line 252, in run
    return self.func(*args, **kwargs)
           ^^^^^^^^^^^^^^^^^^^^^^^^^^
  File "/home/airflow/.local/lib/python3.12/site-packages/airflow/models/baseoperator.py", line 406, in wrapper
    return func(self, *args, **kwargs)
           ^^^^^^^^^^^^^^^^^^^^^^^^^^^
  File "/home/airflow/.local/lib/python3.12/site-packages/airflow/operators/bash.py", line 249, in execute
    raise AirflowException(
airflow.exceptions.AirflowException: Bash command failed. The command returned a non-zero exit code 2.
[2024-09-25T21:39:03.215+0000] {local_task_job_runner.py:266} INFO - Task exited with return code 1
[2024-09-25T21:39:03.223+0000] {taskinstance.py:3900} INFO - 0 downstream tasks scheduled from follow-on schedule check
[2024-09-25T21:39:03.224+0000] {local_task_job_runner.py:245} INFO - ::endgroup::
