[2024-09-25T21:33:00.057+0000] {local_task_job_runner.py:123} INFO - ::group::Pre task execution logs
[2024-09-25T21:33:00.130+0000] {taskinstance.py:2612} INFO - Dependencies all met for dep_context=non-requeueable deps ti=<TaskInstance: AirCrashInvestigation_pipeline.scrape_LoadS3 scheduled__2024-09-23T00:00:00+00:00 [queued]>
[2024-09-25T21:33:00.160+0000] {taskinstance.py:2612} INFO - Dependencies all met for dep_context=requeueable deps ti=<TaskInstance: AirCrashInvestigation_pipeline.scrape_LoadS3 scheduled__2024-09-23T00:00:00+00:00 [queued]>
[2024-09-25T21:33:00.165+0000] {taskinstance.py:2865} INFO - Starting attempt 1 of 2
[2024-09-25T21:33:00.216+0000] {taskinstance.py:2888} INFO - Executing <Task(BashOperator): scrape_LoadS3> on 2024-09-23 00:00:00+00:00
[2024-09-25T21:33:00.230+0000] {standard_task_runner.py:104} INFO - Running: ['***', 'tasks', 'run', 'AirCrashInvestigation_pipeline', 'scrape_LoadS3', 'scheduled__2024-09-23T00:00:00+00:00', '--job-id', '3', '--raw', '--subdir', 'DAGS_FOLDER/main_dag.py', '--cfg-path', '/tmp/tmpkb4axa34']
[2024-09-25T21:33:00.242+0000] {standard_task_runner.py:105} INFO - Job 3: Subtask scrape_LoadS3
[2024-09-25T21:33:00.307+0000] {logging_mixin.py:190} WARNING - /home/***/.local/lib/python3.12/site-packages/***/task/task_runner/standard_task_runner.py:70 DeprecationWarning: This process (pid=189) is multi-threaded, use of fork() may lead to deadlocks in the child.
[2024-09-25T21:33:00.318+0000] {standard_task_runner.py:72} INFO - Started process 195 to run task
[2024-09-25T21:33:00.385+0000] {task_command.py:467} INFO - Running <TaskInstance: AirCrashInvestigation_pipeline.scrape_LoadS3 scheduled__2024-09-23T00:00:00+00:00 [running]> on host fa5d07744004
[2024-09-25T21:33:00.680+0000] {taskinstance.py:3131} INFO - Exporting env vars: AIRFLOW_CTX_DAG_OWNER='***' AIRFLOW_CTX_DAG_ID='AirCrashInvestigation_pipeline' AIRFLOW_CTX_TASK_ID='scrape_LoadS3' AIRFLOW_CTX_EXECUTION_DATE='2024-09-23T00:00:00+00:00' AIRFLOW_CTX_TRY_NUMBER='1' AIRFLOW_CTX_DAG_RUN_ID='scheduled__2024-09-23T00:00:00+00:00'
[2024-09-25T21:33:00.687+0000] {taskinstance.py:731} INFO - ::endgroup::
[2024-09-25T21:33:00.788+0000] {subprocess.py:63} INFO - Tmp dir root location: /tmp
[2024-09-25T21:33:00.791+0000] {subprocess.py:75} INFO - Running command: ['/usr/bin/bash', '-c', 'python3 opt/***/tasks/flightDataWebScrape.py']
[2024-09-25T21:33:00.809+0000] {subprocess.py:86} INFO - Output:
[2024-09-25T21:33:00.978+0000] {subprocess.py:93} INFO - python3: can't open file '/tmp/***tmpn7v5p1pw/opt/***/tasks/flightDataWebScrape.py': [Errno 2] No such file or directory
[2024-09-25T21:33:00.988+0000] {subprocess.py:97} INFO - Command exited with return code 2
[2024-09-25T21:33:01.019+0000] {taskinstance.py:3310} ERROR - Task failed with exception
Traceback (most recent call last):
  File "/home/airflow/.local/lib/python3.12/site-packages/airflow/models/taskinstance.py", line 767, in _execute_task
    result = _execute_callable(context=context, **execute_callable_kwargs)
             ^^^^^^^^^^^^^^^^^^^^^^^^^^^^^^^^^^^^^^^^^^^^^^^^^^^^^^^^^^^^^
  File "/home/airflow/.local/lib/python3.12/site-packages/airflow/models/taskinstance.py", line 733, in _execute_callable
    return ExecutionCallableRunner(
           ^^^^^^^^^^^^^^^^^^^^^^^^
  File "/home/airflow/.local/lib/python3.12/site-packages/airflow/utils/operator_helpers.py", line 252, in run
    return self.func(*args, **kwargs)
           ^^^^^^^^^^^^^^^^^^^^^^^^^^
  File "/home/airflow/.local/lib/python3.12/site-packages/airflow/models/baseoperator.py", line 406, in wrapper
    return func(self, *args, **kwargs)
           ^^^^^^^^^^^^^^^^^^^^^^^^^^^
  File "/home/airflow/.local/lib/python3.12/site-packages/airflow/operators/bash.py", line 249, in execute
    raise AirflowException(
airflow.exceptions.AirflowException: Bash command failed. The command returned a non-zero exit code 2.
[2024-09-25T21:33:01.045+0000] {taskinstance.py:1225} INFO - Marking task as UP_FOR_RETRY. dag_id=AirCrashInvestigation_pipeline, task_id=scrape_LoadS3, run_id=scheduled__2024-09-23T00:00:00+00:00, execution_date=20240923T000000, start_date=20240925T213300, end_date=20240925T213301
[2024-09-25T21:33:01.087+0000] {taskinstance.py:340} INFO - ::group::Post task execution logs
[2024-09-25T21:33:01.095+0000] {standard_task_runner.py:124} ERROR - Failed to execute job 3 for task scrape_LoadS3 (Bash command failed. The command returned a non-zero exit code 2.; 195)
Traceback (most recent call last):
  File "/home/airflow/.local/lib/python3.12/site-packages/airflow/task/task_runner/standard_task_runner.py", line 117, in _start_by_fork
    ret = args.func(args, dag=self.dag)
          ^^^^^^^^^^^^^^^^^^^^^^^^^^^^^
  File "/home/airflow/.local/lib/python3.12/site-packages/airflow/cli/cli_config.py", line 49, in command
    return func(*args, **kwargs)
           ^^^^^^^^^^^^^^^^^^^^^
  File "/home/airflow/.local/lib/python3.12/site-packages/airflow/utils/cli.py", line 115, in wrapper
    return f(*args, **kwargs)
           ^^^^^^^^^^^^^^^^^^
  File "/home/airflow/.local/lib/python3.12/site-packages/airflow/cli/commands/task_command.py", line 483, in task_run
    task_return_code = _run_task_by_selected_method(args, _dag, ti)
                       ^^^^^^^^^^^^^^^^^^^^^^^^^^^^^^^^^^^^^^^^^^^^
  File "/home/airflow/.local/lib/python3.12/site-packages/airflow/cli/commands/task_command.py", line 256, in _run_task_by_selected_method
    return _run_raw_task(args, ti)
           ^^^^^^^^^^^^^^^^^^^^^^^
  File "/home/airflow/.local/lib/python3.12/site-packages/airflow/cli/commands/task_command.py", line 341, in _run_raw_task
    return ti._run_raw_task(
           ^^^^^^^^^^^^^^^^^
  File "/home/airflow/.local/lib/python3.12/site-packages/airflow/utils/session.py", line 97, in wrapper
    return func(*args, session=session, **kwargs)
           ^^^^^^^^^^^^^^^^^^^^^^^^^^^^^^^^^^^^^^
  File "/home/airflow/.local/lib/python3.12/site-packages/airflow/models/taskinstance.py", line 3004, in _run_raw_task
    return _run_raw_task(
           ^^^^^^^^^^^^^^
  File "/home/airflow/.local/lib/python3.12/site-packages/airflow/models/taskinstance.py", line 273, in _run_raw_task
    TaskInstance._execute_task_with_callbacks(
  File "/home/airflow/.local/lib/python3.12/site-packages/airflow/models/taskinstance.py", line 3158, in _execute_task_with_callbacks
    result = self._execute_task(context, task_orig)
             ^^^^^^^^^^^^^^^^^^^^^^^^^^^^^^^^^^^^^^
  File "/home/airflow/.local/lib/python3.12/site-packages/airflow/models/taskinstance.py", line 3182, in _execute_task
    return _execute_task(self, context, task_orig)
           ^^^^^^^^^^^^^^^^^^^^^^^^^^^^^^^^^^^^^^^
  File "/home/airflow/.local/lib/python3.12/site-packages/airflow/models/taskinstance.py", line 767, in _execute_task
    result = _execute_callable(context=context, **execute_callable_kwargs)
             ^^^^^^^^^^^^^^^^^^^^^^^^^^^^^^^^^^^^^^^^^^^^^^^^^^^^^^^^^^^^^
  File "/home/airflow/.local/lib/python3.12/site-packages/airflow/models/taskinstance.py", line 733, in _execute_callable
    return ExecutionCallableRunner(
           ^^^^^^^^^^^^^^^^^^^^^^^^
  File "/home/airflow/.local/lib/python3.12/site-packages/airflow/utils/operator_helpers.py", line 252, in run
    return self.func(*args, **kwargs)
           ^^^^^^^^^^^^^^^^^^^^^^^^^^
  File "/home/airflow/.local/lib/python3.12/site-packages/airflow/models/baseoperator.py", line 406, in wrapper
    return func(self, *args, **kwargs)
           ^^^^^^^^^^^^^^^^^^^^^^^^^^^
  File "/home/airflow/.local/lib/python3.12/site-packages/airflow/operators/bash.py", line 249, in execute
    raise AirflowException(
airflow.exceptions.AirflowException: Bash command failed. The command returned a non-zero exit code 2.
[2024-09-25T21:33:01.140+0000] {local_task_job_runner.py:266} INFO - Task exited with return code 1
[2024-09-25T21:33:01.204+0000] {taskinstance.py:3900} INFO - 0 downstream tasks scheduled from follow-on schedule check
[2024-09-25T21:33:01.216+0000] {local_task_job_runner.py:245} INFO - ::endgroup::
[2024-09-25T21:39:02.995+0000] {local_task_job_runner.py:123} INFO - ::group::Pre task execution logs
[2024-09-25T21:39:03.006+0000] {taskinstance.py:2612} INFO - Dependencies all met for dep_context=non-requeueable deps ti=<TaskInstance: AirCrashInvestigation_pipeline.scrape_LoadS3 scheduled__2024-09-23T00:00:00+00:00 [queued]>
[2024-09-25T21:39:03.012+0000] {taskinstance.py:2612} INFO - Dependencies all met for dep_context=requeueable deps ti=<TaskInstance: AirCrashInvestigation_pipeline.scrape_LoadS3 scheduled__2024-09-23T00:00:00+00:00 [queued]>
[2024-09-25T21:39:03.013+0000] {taskinstance.py:2865} INFO - Starting attempt 1 of 2
[2024-09-25T21:39:03.021+0000] {taskinstance.py:2888} INFO - Executing <Task(BashOperator): scrape_LoadS3> on 2024-09-23 00:00:00+00:00
[2024-09-25T21:39:03.026+0000] {standard_task_runner.py:104} INFO - Running: ['***', 'tasks', 'run', 'AirCrashInvestigation_pipeline', 'scrape_LoadS3', 'scheduled__2024-09-23T00:00:00+00:00', '--job-id', '22', '--raw', '--subdir', 'DAGS_FOLDER/main_dag.py', '--cfg-path', '/tmp/tmpj_f9f1r2']
[2024-09-25T21:39:03.028+0000] {standard_task_runner.py:105} INFO - Job 22: Subtask scrape_LoadS3
[2024-09-25T21:39:03.032+0000] {logging_mixin.py:190} WARNING - /home/***/.local/lib/python3.12/site-packages/***/task/task_runner/standard_task_runner.py:70 DeprecationWarning: This process (pid=405) is multi-threaded, use of fork() may lead to deadlocks in the child.
[2024-09-25T21:39:03.034+0000] {standard_task_runner.py:72} INFO - Started process 407 to run task
[2024-09-25T21:39:03.066+0000] {task_command.py:467} INFO - Running <TaskInstance: AirCrashInvestigation_pipeline.scrape_LoadS3 scheduled__2024-09-23T00:00:00+00:00 [running]> on host fa5d07744004
[2024-09-25T21:39:03.107+0000] {taskinstance.py:3131} INFO - Exporting env vars: AIRFLOW_CTX_DAG_OWNER='***' AIRFLOW_CTX_DAG_ID='AirCrashInvestigation_pipeline' AIRFLOW_CTX_TASK_ID='scrape_LoadS3' AIRFLOW_CTX_EXECUTION_DATE='2024-09-23T00:00:00+00:00' AIRFLOW_CTX_TRY_NUMBER='1' AIRFLOW_CTX_DAG_RUN_ID='scheduled__2024-09-23T00:00:00+00:00'
[2024-09-25T21:39:03.108+0000] {taskinstance.py:731} INFO - ::endgroup::
[2024-09-25T21:39:03.116+0000] {subprocess.py:63} INFO - Tmp dir root location: /tmp
[2024-09-25T21:39:03.117+0000] {subprocess.py:75} INFO - Running command: ['/usr/bin/bash', '-c', 'python3 ./opt/***/tasks/flightDataWebScrape.py']
[2024-09-25T21:39:03.123+0000] {subprocess.py:86} INFO - Output:
[2024-09-25T21:39:03.146+0000] {subprocess.py:93} INFO - python3: can't open file '/tmp/***tmpkeokbp4y/./opt/***/tasks/flightDataWebScrape.py': [Errno 2] No such file or directory
[2024-09-25T21:39:03.150+0000] {subprocess.py:97} INFO - Command exited with return code 2
[2024-09-25T21:39:03.162+0000] {taskinstance.py:3310} ERROR - Task failed with exception
Traceback (most recent call last):
  File "/home/airflow/.local/lib/python3.12/site-packages/airflow/models/taskinstance.py", line 767, in _execute_task
    result = _execute_callable(context=context, **execute_callable_kwargs)
             ^^^^^^^^^^^^^^^^^^^^^^^^^^^^^^^^^^^^^^^^^^^^^^^^^^^^^^^^^^^^^
  File "/home/airflow/.local/lib/python3.12/site-packages/airflow/models/taskinstance.py", line 733, in _execute_callable
    return ExecutionCallableRunner(
           ^^^^^^^^^^^^^^^^^^^^^^^^
  File "/home/airflow/.local/lib/python3.12/site-packages/airflow/utils/operator_helpers.py", line 252, in run
    return self.func(*args, **kwargs)
           ^^^^^^^^^^^^^^^^^^^^^^^^^^
  File "/home/airflow/.local/lib/python3.12/site-packages/airflow/models/baseoperator.py", line 406, in wrapper
    return func(self, *args, **kwargs)
           ^^^^^^^^^^^^^^^^^^^^^^^^^^^
  File "/home/airflow/.local/lib/python3.12/site-packages/airflow/operators/bash.py", line 249, in execute
    raise AirflowException(
airflow.exceptions.AirflowException: Bash command failed. The command returned a non-zero exit code 2.
[2024-09-25T21:39:03.170+0000] {taskinstance.py:1225} INFO - Marking task as UP_FOR_RETRY. dag_id=AirCrashInvestigation_pipeline, task_id=scrape_LoadS3, run_id=scheduled__2024-09-23T00:00:00+00:00, execution_date=20240923T000000, start_date=20240925T213903, end_date=20240925T213903
[2024-09-25T21:39:03.181+0000] {taskinstance.py:340} INFO - ::group::Post task execution logs
[2024-09-25T21:39:03.183+0000] {standard_task_runner.py:124} ERROR - Failed to execute job 22 for task scrape_LoadS3 (Bash command failed. The command returned a non-zero exit code 2.; 407)
Traceback (most recent call last):
  File "/home/airflow/.local/lib/python3.12/site-packages/airflow/task/task_runner/standard_task_runner.py", line 117, in _start_by_fork
    ret = args.func(args, dag=self.dag)
          ^^^^^^^^^^^^^^^^^^^^^^^^^^^^^
  File "/home/airflow/.local/lib/python3.12/site-packages/airflow/cli/cli_config.py", line 49, in command
    return func(*args, **kwargs)
           ^^^^^^^^^^^^^^^^^^^^^
  File "/home/airflow/.local/lib/python3.12/site-packages/airflow/utils/cli.py", line 115, in wrapper
    return f(*args, **kwargs)
           ^^^^^^^^^^^^^^^^^^
  File "/home/airflow/.local/lib/python3.12/site-packages/airflow/cli/commands/task_command.py", line 483, in task_run
    task_return_code = _run_task_by_selected_method(args, _dag, ti)
                       ^^^^^^^^^^^^^^^^^^^^^^^^^^^^^^^^^^^^^^^^^^^^
  File "/home/airflow/.local/lib/python3.12/site-packages/airflow/cli/commands/task_command.py", line 256, in _run_task_by_selected_method
    return _run_raw_task(args, ti)
           ^^^^^^^^^^^^^^^^^^^^^^^
  File "/home/airflow/.local/lib/python3.12/site-packages/airflow/cli/commands/task_command.py", line 341, in _run_raw_task
    return ti._run_raw_task(
           ^^^^^^^^^^^^^^^^^
  File "/home/airflow/.local/lib/python3.12/site-packages/airflow/utils/session.py", line 97, in wrapper
    return func(*args, session=session, **kwargs)
           ^^^^^^^^^^^^^^^^^^^^^^^^^^^^^^^^^^^^^^
  File "/home/airflow/.local/lib/python3.12/site-packages/airflow/models/taskinstance.py", line 3004, in _run_raw_task
    return _run_raw_task(
           ^^^^^^^^^^^^^^
  File "/home/airflow/.local/lib/python3.12/site-packages/airflow/models/taskinstance.py", line 273, in _run_raw_task
    TaskInstance._execute_task_with_callbacks(
  File "/home/airflow/.local/lib/python3.12/site-packages/airflow/models/taskinstance.py", line 3158, in _execute_task_with_callbacks
    result = self._execute_task(context, task_orig)
             ^^^^^^^^^^^^^^^^^^^^^^^^^^^^^^^^^^^^^^
  File "/home/airflow/.local/lib/python3.12/site-packages/airflow/models/taskinstance.py", line 3182, in _execute_task
    return _execute_task(self, context, task_orig)
           ^^^^^^^^^^^^^^^^^^^^^^^^^^^^^^^^^^^^^^^
  File "/home/airflow/.local/lib/python3.12/site-packages/airflow/models/taskinstance.py", line 767, in _execute_task
    result = _execute_callable(context=context, **execute_callable_kwargs)
             ^^^^^^^^^^^^^^^^^^^^^^^^^^^^^^^^^^^^^^^^^^^^^^^^^^^^^^^^^^^^^
  File "/home/airflow/.local/lib/python3.12/site-packages/airflow/models/taskinstance.py", line 733, in _execute_callable
    return ExecutionCallableRunner(
           ^^^^^^^^^^^^^^^^^^^^^^^^
  File "/home/airflow/.local/lib/python3.12/site-packages/airflow/utils/operator_helpers.py", line 252, in run
    return self.func(*args, **kwargs)
           ^^^^^^^^^^^^^^^^^^^^^^^^^^
  File "/home/airflow/.local/lib/python3.12/site-packages/airflow/models/baseoperator.py", line 406, in wrapper
    return func(self, *args, **kwargs)
           ^^^^^^^^^^^^^^^^^^^^^^^^^^^
  File "/home/airflow/.local/lib/python3.12/site-packages/airflow/operators/bash.py", line 249, in execute
    raise AirflowException(
airflow.exceptions.AirflowException: Bash command failed. The command returned a non-zero exit code 2.
[2024-09-25T21:39:03.215+0000] {local_task_job_runner.py:266} INFO - Task exited with return code 1
[2024-09-25T21:39:03.223+0000] {taskinstance.py:3900} INFO - 0 downstream tasks scheduled from follow-on schedule check
[2024-09-25T21:39:03.224+0000] {local_task_job_runner.py:245} INFO - ::endgroup::
[2024-09-29T02:10:37.644+0000] {local_task_job_runner.py:120} INFO - ::group::Pre task execution logs
[2024-09-29T02:10:37.688+0000] {taskinstance.py:2073} INFO - Dependencies all met for dep_context=non-requeueable deps ti=<TaskInstance: AirCrashInvestigation_pipeline.scrape_LoadS3 scheduled__2024-09-23T00:00:00+00:00 [queued]>
[2024-09-29T02:10:37.708+0000] {taskinstance.py:2073} INFO - Dependencies all met for dep_context=requeueable deps ti=<TaskInstance: AirCrashInvestigation_pipeline.scrape_LoadS3 scheduled__2024-09-23T00:00:00+00:00 [queued]>
[2024-09-29T02:10:37.709+0000] {taskinstance.py:2303} INFO - Starting attempt 1 of 2
[2024-09-29T02:10:37.742+0000] {taskinstance.py:2327} INFO - Executing <Task(BashOperator): scrape_LoadS3> on 2024-09-23 00:00:00+00:00
[2024-09-29T02:10:37.771+0000] {warnings.py:110} WARNING - /home/***/.local/lib/python3.12/site-packages/***/task/task_runner/standard_task_runner.py:61: DeprecationWarning: This process (pid=65) is multi-threaded, use of fork() may lead to deadlocks in the child.
  pid = os.fork()

[2024-09-29T02:10:37.772+0000] {standard_task_runner.py:63} INFO - Started process 73 to run task
[2024-09-29T02:10:37.753+0000] {standard_task_runner.py:90} INFO - Running: ['***', 'tasks', 'run', 'AirCrashInvestigation_pipeline', 'scrape_LoadS3', 'scheduled__2024-09-23T00:00:00+00:00', '--job-id', '4', '--raw', '--subdir', 'DAGS_FOLDER/main_dag.py', '--cfg-path', '/tmp/tmp21ee_moj']
[2024-09-29T02:10:37.781+0000] {standard_task_runner.py:91} INFO - Job 4: Subtask scrape_LoadS3
[2024-09-29T02:10:37.926+0000] {task_command.py:426} INFO - Running <TaskInstance: AirCrashInvestigation_pipeline.scrape_LoadS3 scheduled__2024-09-23T00:00:00+00:00 [running]> on host 7b437d7ff517
[2024-09-29T02:10:38.115+0000] {taskinstance.py:2644} INFO - Exporting env vars: AIRFLOW_CTX_DAG_OWNER='***' AIRFLOW_CTX_DAG_ID='AirCrashInvestigation_pipeline' AIRFLOW_CTX_TASK_ID='scrape_LoadS3' AIRFLOW_CTX_EXECUTION_DATE='2024-09-23T00:00:00+00:00' AIRFLOW_CTX_TRY_NUMBER='1' AIRFLOW_CTX_DAG_RUN_ID='scheduled__2024-09-23T00:00:00+00:00'
[2024-09-29T02:10:38.118+0000] {taskinstance.py:430} INFO - ::endgroup::
[2024-09-29T02:10:38.145+0000] {subprocess.py:63} INFO - Tmp dir root location: /tmp
[2024-09-29T02:10:38.150+0000] {subprocess.py:75} INFO - Running command: ['/usr/bin/bash', '-c', 'python3 /opt/***/tasks/flightDataWebScrape.py']
[2024-09-29T02:10:38.163+0000] {subprocess.py:86} INFO - Output:
[2024-09-29T02:11:23.123+0000] {local_task_job_runner.py:310} WARNING - State of this instance has been externally set to queued. Terminating instance.
[2024-09-29T02:11:23.124+0000] {local_task_job_runner.py:222} INFO - ::endgroup::
[2024-09-29T02:11:23.125+0000] {process_utils.py:132} INFO - Sending 15 to group 73. PIDs of all processes in the group: [77, 73]
[2024-09-29T02:11:23.125+0000] {process_utils.py:87} INFO - Sending the signal 15 to group 73
[2024-09-29T02:11:23.126+0000] {taskinstance.py:2607} ERROR - Received SIGTERM. Terminating subprocesses.
[2024-09-29T02:11:23.126+0000] {subprocess.py:104} INFO - Sending SIGTERM signal to process group
[2024-09-29T02:11:23.126+0000] {taskinstance.py:441} INFO - ::group::Post task execution logs
[2024-09-29T02:11:23.143+0000] {taskinstance.py:2890} ERROR - Task failed with exception
Traceback (most recent call last):
  File "/home/airflow/.local/lib/python3.12/site-packages/airflow/models/taskinstance.py", line 465, in _execute_task
    result = _execute_callable(context=context, **execute_callable_kwargs)
             ^^^^^^^^^^^^^^^^^^^^^^^^^^^^^^^^^^^^^^^^^^^^^^^^^^^^^^^^^^^^^
  File "/home/airflow/.local/lib/python3.12/site-packages/airflow/models/taskinstance.py", line 432, in _execute_callable
    return execute_callable(context=context, **execute_callable_kwargs)
           ^^^^^^^^^^^^^^^^^^^^^^^^^^^^^^^^^^^^^^^^^^^^^^^^^^^^^^^^^^^^
  File "/home/airflow/.local/lib/python3.12/site-packages/airflow/models/baseoperator.py", line 400, in wrapper
    return func(self, *args, **kwargs)
           ^^^^^^^^^^^^^^^^^^^^^^^^^^^
  File "/home/airflow/.local/lib/python3.12/site-packages/airflow/operators/bash.py", line 234, in execute
    result = self.subprocess_hook.run_command(
             ^^^^^^^^^^^^^^^^^^^^^^^^^^^^^^^^^
  File "/home/airflow/.local/lib/python3.12/site-packages/airflow/hooks/subprocess.py", line 91, in run_command
    for raw_line in iter(self.sub_process.stdout.readline, b""):
  File "/home/airflow/.local/lib/python3.12/site-packages/airflow/models/taskinstance.py", line 2609, in signal_handler
    raise AirflowTaskTerminated("Task received SIGTERM signal")
airflow.exceptions.AirflowTaskTerminated: Task received SIGTERM signal
[2024-09-29T02:11:23.150+0000] {taskinstance.py:1205} INFO - Marking task as UP_FOR_RETRY. dag_id=AirCrashInvestigation_pipeline, task_id=scrape_LoadS3, execution_date=20240923T000000, start_date=, end_date=20240929T021123
[2024-09-29T02:11:23.163+0000] {standard_task_runner.py:110} ERROR - Failed to execute job 4 for task scrape_LoadS3 ((psycopg2.errors.UniqueViolation) duplicate key value violates unique constraint "dag_run_dag_id_execution_date_key"
DETAIL:  Key (dag_id, execution_date)=(AirCrashInvestigation_pipeline, 2024-09-23 00:00:00+00) already exists.

[SQL: INSERT INTO dag_run (id, dag_id, queued_at, execution_date, start_date, end_date, state, run_id, creating_job_id, external_trigger, run_type, conf, data_interval_start, data_interval_end, last_scheduling_decision, dag_hash, log_template_id, updated_at, clear_number) VALUES (%(id)s, %(dag_id)s, %(queued_at)s, %(execution_date)s, %(start_date)s, %(end_date)s, %(state)s, %(run_id)s, %(creating_job_id)s, %(external_trigger)s, %(run_type)s, %(conf)s, %(data_interval_start)s, %(data_interval_end)s, %(last_scheduling_decision)s, %(dag_hash)s, %(log_template_id)s, %(updated_at)s, %(clear_number)s)]
[parameters: {'id': 1, 'dag_id': 'AirCrashInvestigation_pipeline', 'queued_at': datetime.datetime(2024, 9, 29, 2, 10, 36, 132165, tzinfo=Timezone('UTC')), 'execution_date': datetime.datetime(2024, 9, 23, 0, 0, tzinfo=Timezone('UTC')), 'start_date': datetime.datetime(2024, 9, 29, 2, 10, 36, 150964, tzinfo=Timezone('UTC')), 'end_date': None, 'state': 'running', 'run_id': 'scheduled__2024-09-23T00:00:00+00:00', 'creating_job_id': 2, 'external_trigger': False, 'run_type': 'scheduled', 'conf': <psycopg2.extensions.Binary object at 0xffffa097ce70>, 'data_interval_start': datetime.datetime(2024, 9, 23, 0, 0, tzinfo=Timezone('UTC')), 'data_interval_end': datetime.datetime(2024, 9, 24, 0, 0, tzinfo=Timezone('UTC')), 'last_scheduling_decision': datetime.datetime(2024, 9, 29, 2, 10, 36, 853689, tzinfo=Timezone('UTC')), 'dag_hash': '430e9cf2cc72fa71822c5198d39b3e9d', 'log_template_id': 2, 'updated_at': datetime.datetime(2024, 9, 29, 2, 10, 36, 857050, tzinfo=Timezone('UTC')), 'clear_number': 0}]
(Background on this error at: https://sqlalche.me/e/14/gkpj); 73)
[2024-09-29T02:11:23.188+0000] {process_utils.py:80} INFO - Process psutil.Process(pid=77, status='terminated', started='02:10:37') (77) terminated with exit code None
[2024-09-29T02:11:23.189+0000] {process_utils.py:80} INFO - Process psutil.Process(pid=73, status='terminated', exitcode=1, started='02:10:36') (73) terminated with exit code 1
[2024-09-29T02:11:24.927+0000] {local_task_job_runner.py:120} INFO - ::group::Pre task execution logs
[2024-09-29T02:11:24.990+0000] {taskinstance.py:2063} INFO - Dependencies not met for <TaskInstance: AirCrashInvestigation_pipeline.scrape_LoadS3 scheduled__2024-09-23T00:00:00+00:00 [skipped]>, dependency 'Task Instance State' FAILED: Task is in the 'skipped' state.
[2024-09-29T02:11:25.008+0000] {local_task_job_runner.py:163} INFO - Task is not able to be run
[2024-09-30T03:09:37.940+0000] {local_task_job_runner.py:120} INFO - ::group::Pre task execution logs
[2024-09-30T03:09:37.971+0000] {taskinstance.py:2073} INFO - Dependencies all met for dep_context=non-requeueable deps ti=<TaskInstance: AirCrashInvestigation_pipeline.scrape_LoadS3 scheduled__2024-09-23T00:00:00+00:00 [queued]>
[2024-09-30T03:09:37.982+0000] {taskinstance.py:2073} INFO - Dependencies all met for dep_context=requeueable deps ti=<TaskInstance: AirCrashInvestigation_pipeline.scrape_LoadS3 scheduled__2024-09-23T00:00:00+00:00 [queued]>
[2024-09-30T03:09:37.985+0000] {taskinstance.py:2303} INFO - Starting attempt 1 of 2
[2024-09-30T03:09:38.006+0000] {taskinstance.py:2327} INFO - Executing <Task(BashOperator): scrape_LoadS3> on 2024-09-23 00:00:00+00:00
[2024-09-30T03:09:38.011+0000] {warnings.py:110} WARNING - /home/***/.local/lib/python3.12/site-packages/***/task/task_runner/standard_task_runner.py:61: DeprecationWarning: This process (pid=88) is multi-threaded, use of fork() may lead to deadlocks in the child.
  pid = os.fork()

[2024-09-30T03:09:38.016+0000] {standard_task_runner.py:63} INFO - Started process 95 to run task
[2024-09-30T03:09:38.016+0000] {standard_task_runner.py:90} INFO - Running: ['***', 'tasks', 'run', 'AirCrashInvestigation_pipeline', 'scrape_LoadS3', 'scheduled__2024-09-23T00:00:00+00:00', '--job-id', '4', '--raw', '--subdir', 'DAGS_FOLDER/main_dag.py', '--cfg-path', '/tmp/tmpd5daw5jh']
[2024-09-30T03:09:38.020+0000] {standard_task_runner.py:91} INFO - Job 4: Subtask scrape_LoadS3
[2024-09-30T03:09:38.091+0000] {task_command.py:426} INFO - Running <TaskInstance: AirCrashInvestigation_pipeline.scrape_LoadS3 scheduled__2024-09-23T00:00:00+00:00 [running]> on host 60abf2d32f6d
[2024-09-30T03:09:38.180+0000] {taskinstance.py:2644} INFO - Exporting env vars: AIRFLOW_CTX_DAG_OWNER='***' AIRFLOW_CTX_DAG_ID='AirCrashInvestigation_pipeline' AIRFLOW_CTX_TASK_ID='scrape_LoadS3' AIRFLOW_CTX_EXECUTION_DATE='2024-09-23T00:00:00+00:00' AIRFLOW_CTX_TRY_NUMBER='1' AIRFLOW_CTX_DAG_RUN_ID='scheduled__2024-09-23T00:00:00+00:00'
[2024-09-30T03:09:38.181+0000] {taskinstance.py:430} INFO - ::endgroup::
[2024-09-30T03:09:38.198+0000] {subprocess.py:63} INFO - Tmp dir root location: /tmp
[2024-09-30T03:09:38.199+0000] {subprocess.py:75} INFO - Running command: ['/usr/bin/bash', '-c', 'python3 /opt/***/tasks/flightDataWebScrape.py']
[2024-09-30T03:09:38.215+0000] {subprocess.py:86} INFO - Output:
[2024-09-30T03:09:39.857+0000] {subprocess.py:93} INFO - Traceback (most recent call last):
[2024-09-30T03:09:39.858+0000] {subprocess.py:93} INFO -   File "/opt/***/tasks/flightDataWebScrape.py", line 5, in <module>
[2024-09-30T03:09:39.859+0000] {subprocess.py:93} INFO -     from pipelineActions import *
[2024-09-30T03:09:39.859+0000] {subprocess.py:93} INFO -   File "/opt/***/tasks/pipelineActions.py", line 13, in <module>
[2024-09-30T03:09:39.859+0000] {subprocess.py:93} INFO -     config.read(config_file_path)
[2024-09-30T03:09:39.860+0000] {subprocess.py:93} INFO -   File "/usr/local/lib/python3.12/configparser.py", line 684, in read
[2024-09-30T03:09:39.861+0000] {subprocess.py:93} INFO -     self._read(fp, filename)
[2024-09-30T03:09:39.861+0000] {subprocess.py:93} INFO -   File "/usr/local/lib/python3.12/configparser.py", line 1063, in _read
[2024-09-30T03:09:39.862+0000] {subprocess.py:93} INFO -     raise MissingSectionHeaderError(fpname, lineno, line)
[2024-09-30T03:09:39.862+0000] {subprocess.py:93} INFO - configparser.MissingSectionHeaderError: File contains no section headers.
[2024-09-30T03:09:39.862+0000] {subprocess.py:93} INFO - file: PosixPath('/opt/***/tasks/pipeline.conf'), line: 1
[2024-09-30T03:09:39.863+0000] {subprocess.py:93} INFO - 'bucket_name = "flightcrashbucket"\n'
[2024-09-30T03:09:40.041+0000] {subprocess.py:97} INFO - Command exited with return code 1
[2024-09-30T03:09:40.041+0000] {taskinstance.py:441} INFO - ::group::Post task execution logs
[2024-09-30T03:09:40.064+0000] {taskinstance.py:2890} ERROR - Task failed with exception
Traceback (most recent call last):
  File "/home/airflow/.local/lib/python3.12/site-packages/airflow/models/taskinstance.py", line 465, in _execute_task
    result = _execute_callable(context=context, **execute_callable_kwargs)
             ^^^^^^^^^^^^^^^^^^^^^^^^^^^^^^^^^^^^^^^^^^^^^^^^^^^^^^^^^^^^^
  File "/home/airflow/.local/lib/python3.12/site-packages/airflow/models/taskinstance.py", line 432, in _execute_callable
    return execute_callable(context=context, **execute_callable_kwargs)
           ^^^^^^^^^^^^^^^^^^^^^^^^^^^^^^^^^^^^^^^^^^^^^^^^^^^^^^^^^^^^
  File "/home/airflow/.local/lib/python3.12/site-packages/airflow/models/baseoperator.py", line 400, in wrapper
    return func(self, *args, **kwargs)
           ^^^^^^^^^^^^^^^^^^^^^^^^^^^
  File "/home/airflow/.local/lib/python3.12/site-packages/airflow/operators/bash.py", line 243, in execute
    raise AirflowException(
airflow.exceptions.AirflowException: Bash command failed. The command returned a non-zero exit code 1.
[2024-09-30T03:09:40.076+0000] {taskinstance.py:1205} INFO - Marking task as UP_FOR_RETRY. dag_id=AirCrashInvestigation_pipeline, task_id=scrape_LoadS3, execution_date=20240923T000000, start_date=20240930T030937, end_date=20240930T030940
[2024-09-30T03:09:40.091+0000] {standard_task_runner.py:110} ERROR - Failed to execute job 4 for task scrape_LoadS3 (Bash command failed. The command returned a non-zero exit code 1.; 95)
[2024-09-30T03:09:40.135+0000] {local_task_job_runner.py:240} INFO - Task exited with return code 1
[2024-09-30T03:09:40.172+0000] {taskinstance.py:3482} INFO - 0 downstream tasks scheduled from follow-on schedule check
[2024-09-30T03:09:40.173+0000] {local_task_job_runner.py:222} INFO - ::endgroup::
[2024-10-02T00:38:31.204+0000] {local_task_job_runner.py:120} INFO - ::group::Pre task execution logs
[2024-10-02T00:38:31.221+0000] {taskinstance.py:2073} INFO - Dependencies all met for dep_context=non-requeueable deps ti=<TaskInstance: AirCrashInvestigation_pipeline.scrape_LoadS3 scheduled__2024-09-23T00:00:00+00:00 [queued]>
[2024-10-02T00:38:31.232+0000] {taskinstance.py:2073} INFO - Dependencies all met for dep_context=requeueable deps ti=<TaskInstance: AirCrashInvestigation_pipeline.scrape_LoadS3 scheduled__2024-09-23T00:00:00+00:00 [queued]>
[2024-10-02T00:38:31.233+0000] {taskinstance.py:2303} INFO - Starting attempt 1 of 2
[2024-10-02T00:38:31.249+0000] {taskinstance.py:2327} INFO - Executing <Task(BashOperator): scrape_LoadS3> on 2024-09-23 00:00:00+00:00
[2024-10-02T00:38:31.257+0000] {warnings.py:110} WARNING - /home/***/.local/lib/python3.12/site-packages/***/task/task_runner/standard_task_runner.py:61: DeprecationWarning: This process (pid=66) is multi-threaded, use of fork() may lead to deadlocks in the child.
  pid = os.fork()

[2024-10-02T00:38:31.263+0000] {standard_task_runner.py:63} INFO - Started process 74 to run task
[2024-10-02T00:38:31.261+0000] {standard_task_runner.py:90} INFO - Running: ['***', 'tasks', 'run', 'AirCrashInvestigation_pipeline', 'scrape_LoadS3', 'scheduled__2024-09-23T00:00:00+00:00', '--job-id', '4', '--raw', '--subdir', 'DAGS_FOLDER/main_dag.py', '--cfg-path', '/tmp/tmp8q294345']
[2024-10-02T00:38:31.271+0000] {standard_task_runner.py:91} INFO - Job 4: Subtask scrape_LoadS3
[2024-10-02T00:38:31.368+0000] {task_command.py:426} INFO - Running <TaskInstance: AirCrashInvestigation_pipeline.scrape_LoadS3 scheduled__2024-09-23T00:00:00+00:00 [running]> on host 5050c2f305ab
[2024-10-02T00:38:31.614+0000] {taskinstance.py:2644} INFO - Exporting env vars: AIRFLOW_CTX_DAG_OWNER='***' AIRFLOW_CTX_DAG_ID='AirCrashInvestigation_pipeline' AIRFLOW_CTX_TASK_ID='scrape_LoadS3' AIRFLOW_CTX_EXECUTION_DATE='2024-09-23T00:00:00+00:00' AIRFLOW_CTX_TRY_NUMBER='1' AIRFLOW_CTX_DAG_RUN_ID='scheduled__2024-09-23T00:00:00+00:00'
[2024-10-02T00:38:31.614+0000] {taskinstance.py:430} INFO - ::endgroup::
[2024-10-02T00:38:31.668+0000] {subprocess.py:63} INFO - Tmp dir root location: /tmp
[2024-10-02T00:38:31.670+0000] {subprocess.py:75} INFO - Running command: ['/usr/bin/bash', '-c', 'python3 /opt/***/tasks/flightDataWebScrape.py']
[2024-10-02T00:38:31.705+0000] {subprocess.py:86} INFO - Output:
[2024-10-02T00:38:51.418+0000] {local_task_job_runner.py:310} WARNING - State of this instance has been externally set to failed. Terminating instance.
[2024-10-02T00:38:51.420+0000] {local_task_job_runner.py:222} INFO - ::endgroup::
[2024-10-02T00:38:51.421+0000] {process_utils.py:132} INFO - Sending 15 to group 74. PIDs of all processes in the group: [79, 74]
[2024-10-02T00:38:51.421+0000] {process_utils.py:87} INFO - Sending the signal 15 to group 74
[2024-10-02T00:38:51.421+0000] {taskinstance.py:2607} ERROR - Received SIGTERM. Terminating subprocesses.
[2024-10-02T00:38:51.422+0000] {subprocess.py:104} INFO - Sending SIGTERM signal to process group
[2024-10-02T00:38:51.423+0000] {taskinstance.py:441} INFO - ::group::Post task execution logs
[2024-10-02T00:38:51.451+0000] {process_utils.py:80} INFO - Process psutil.Process(pid=79, status='terminated', started='00:38:31') (79) terminated with exit code None
[2024-10-02T00:38:51.452+0000] {process_utils.py:80} INFO - Process psutil.Process(pid=74, status='terminated', exitcode=0, started='00:38:31') (74) terminated with exit code 0
[2024-10-02T02:09:33.601+0000] {local_task_job_runner.py:120} INFO - ::group::Pre task execution logs
[2024-10-02T02:09:33.625+0000] {taskinstance.py:2073} INFO - Dependencies all met for dep_context=non-requeueable deps ti=<TaskInstance: AirCrashInvestigation_pipeline.scrape_LoadS3 scheduled__2024-09-23T00:00:00+00:00 [queued]>
[2024-10-02T02:09:33.637+0000] {taskinstance.py:2073} INFO - Dependencies all met for dep_context=requeueable deps ti=<TaskInstance: AirCrashInvestigation_pipeline.scrape_LoadS3 scheduled__2024-09-23T00:00:00+00:00 [queued]>
[2024-10-02T02:09:33.638+0000] {taskinstance.py:2303} INFO - Starting attempt 1 of 2
[2024-10-02T02:09:33.681+0000] {taskinstance.py:2327} INFO - Executing <Task(BashOperator): scrape_LoadS3> on 2024-09-23 00:00:00+00:00
[2024-10-02T02:09:33.684+0000] {warnings.py:110} WARNING - /home/***/.local/lib/python3.12/site-packages/***/task/task_runner/standard_task_runner.py:61: DeprecationWarning: This process (pid=72) is multi-threaded, use of fork() may lead to deadlocks in the child.
  pid = os.fork()

[2024-10-02T02:09:33.689+0000] {standard_task_runner.py:90} INFO - Running: ['***', 'tasks', 'run', 'AirCrashInvestigation_pipeline', 'scrape_LoadS3', 'scheduled__2024-09-23T00:00:00+00:00', '--job-id', '3', '--raw', '--subdir', 'DAGS_FOLDER/main_dag.py', '--cfg-path', '/tmp/tmpbclse89u']
[2024-10-02T02:09:33.692+0000] {standard_task_runner.py:91} INFO - Job 3: Subtask scrape_LoadS3
[2024-10-02T02:09:33.692+0000] {standard_task_runner.py:63} INFO - Started process 77 to run task
[2024-10-02T02:09:33.773+0000] {task_command.py:426} INFO - Running <TaskInstance: AirCrashInvestigation_pipeline.scrape_LoadS3 scheduled__2024-09-23T00:00:00+00:00 [running]> on host ac8ffcfe4778
[2024-10-02T02:09:33.880+0000] {taskinstance.py:2644} INFO - Exporting env vars: AIRFLOW_CTX_DAG_OWNER='***' AIRFLOW_CTX_DAG_ID='AirCrashInvestigation_pipeline' AIRFLOW_CTX_TASK_ID='scrape_LoadS3' AIRFLOW_CTX_EXECUTION_DATE='2024-09-23T00:00:00+00:00' AIRFLOW_CTX_TRY_NUMBER='1' AIRFLOW_CTX_DAG_RUN_ID='scheduled__2024-09-23T00:00:00+00:00'
[2024-10-02T02:09:33.880+0000] {taskinstance.py:430} INFO - ::endgroup::
[2024-10-02T02:09:33.898+0000] {subprocess.py:63} INFO - Tmp dir root location: /tmp
[2024-10-02T02:09:33.899+0000] {subprocess.py:75} INFO - Running command: ['/usr/bin/bash', '-c', 'python3 /opt/***/tasks/flightDataWebScrape.py']
[2024-10-02T02:09:33.916+0000] {subprocess.py:86} INFO - Output:
[2024-10-02T02:11:44.095+0000] {subprocess.py:93} INFO - 1920 data accessed
[2024-10-02T02:11:44.096+0000] {subprocess.py:93} INFO - fetched empty data in1920
[2024-10-02T02:11:44.099+0000] {subprocess.py:93} INFO - fetched empty data in1920
[2024-10-02T02:11:44.099+0000] {subprocess.py:93} INFO - fetched empty data in1920
[2024-10-02T02:11:44.099+0000] {subprocess.py:93} INFO - fetched empty data in1920
[2024-10-02T02:11:44.099+0000] {subprocess.py:93} INFO - fetched empty data in1920
[2024-10-02T02:11:44.099+0000] {subprocess.py:93} INFO - fetched empty data in1920
[2024-10-02T02:11:44.100+0000] {subprocess.py:93} INFO - fetched empty data in1920
[2024-10-02T02:11:44.100+0000] {subprocess.py:93} INFO - fetched empty data in1920
[2024-10-02T02:11:44.100+0000] {subprocess.py:93} INFO - fetched empty data in1920
[2024-10-02T02:11:44.100+0000] {subprocess.py:93} INFO - fetched empty data in1920
[2024-10-02T02:11:44.101+0000] {subprocess.py:93} INFO - fetched empty data in1920
[2024-10-02T02:11:44.101+0000] {subprocess.py:93} INFO - fetched empty data in1920
[2024-10-02T02:11:44.101+0000] {subprocess.py:93} INFO - fetched empty data in1920
[2024-10-02T02:11:44.101+0000] {subprocess.py:93} INFO - fetched empty data in1920
[2024-10-02T02:11:44.101+0000] {subprocess.py:93} INFO - fetched empty data in1920
[2024-10-02T02:11:44.101+0000] {subprocess.py:93} INFO - Traceback (most recent call last):
[2024-10-02T02:11:44.101+0000] {subprocess.py:93} INFO -   File "/home/***/.local/lib/python3.12/site-packages/urllib3/connection.py", line 174, in _new_conn
[2024-10-02T02:11:44.102+0000] {subprocess.py:93} INFO -     conn = connection.create_connection(
[2024-10-02T02:11:44.102+0000] {subprocess.py:93} INFO -            ^^^^^^^^^^^^^^^^^^^^^^^^^^^^^
[2024-10-02T02:11:44.102+0000] {subprocess.py:93} INFO -   File "/home/***/.local/lib/python3.12/site-packages/urllib3/util/connection.py", line 95, in create_connection
[2024-10-02T02:11:44.102+0000] {subprocess.py:93} INFO -     raise err
[2024-10-02T02:11:44.102+0000] {subprocess.py:93} INFO -   File "/home/***/.local/lib/python3.12/site-packages/urllib3/util/connection.py", line 85, in create_connection
[2024-10-02T02:11:44.102+0000] {subprocess.py:93} INFO -     sock.connect(sa)
[2024-10-02T02:11:44.103+0000] {subprocess.py:93} INFO - ConnectionRefusedError: [Errno 111] Connection refused
[2024-10-02T02:11:44.103+0000] {subprocess.py:93} INFO - 
[2024-10-02T02:11:44.103+0000] {subprocess.py:93} INFO - During handling of the above exception, another exception occurred:
[2024-10-02T02:11:44.103+0000] {subprocess.py:93} INFO - 
[2024-10-02T02:11:44.103+0000] {subprocess.py:93} INFO - Traceback (most recent call last):
[2024-10-02T02:11:44.103+0000] {subprocess.py:93} INFO -   File "/home/***/.local/lib/python3.12/site-packages/urllib3/connectionpool.py", line 715, in urlopen
[2024-10-02T02:11:44.103+0000] {subprocess.py:93} INFO -     httplib_response = self._make_request(
[2024-10-02T02:11:44.104+0000] {subprocess.py:93} INFO -                        ^^^^^^^^^^^^^^^^^^^
[2024-10-02T02:11:44.104+0000] {subprocess.py:93} INFO -   File "/home/***/.local/lib/python3.12/site-packages/urllib3/connectionpool.py", line 404, in _make_request
[2024-10-02T02:11:44.104+0000] {subprocess.py:93} INFO -     self._validate_conn(conn)
[2024-10-02T02:11:44.104+0000] {subprocess.py:93} INFO -   File "/home/***/.local/lib/python3.12/site-packages/urllib3/connectionpool.py", line 1058, in _validate_conn
[2024-10-02T02:11:44.104+0000] {subprocess.py:93} INFO -     conn.connect()
[2024-10-02T02:11:44.104+0000] {subprocess.py:93} INFO -   File "/home/***/.local/lib/python3.12/site-packages/urllib3/connection.py", line 363, in connect
[2024-10-02T02:11:44.105+0000] {subprocess.py:93} INFO -     self.sock = conn = self._new_conn()
[2024-10-02T02:11:44.105+0000] {subprocess.py:93} INFO -                        ^^^^^^^^^^^^^^^^
[2024-10-02T02:11:44.105+0000] {subprocess.py:93} INFO -   File "/home/***/.local/lib/python3.12/site-packages/urllib3/connection.py", line 186, in _new_conn
[2024-10-02T02:11:44.105+0000] {subprocess.py:93} INFO -     raise NewConnectionError(
[2024-10-02T02:11:44.105+0000] {subprocess.py:93} INFO - urllib3.exceptions.NewConnectionError: <urllib3.connection.HTTPSConnection object at 0xffffba0e1460>: Failed to establish a new connection: [Errno 111] Connection refused
[2024-10-02T02:11:44.105+0000] {subprocess.py:93} INFO - 
[2024-10-02T02:11:44.105+0000] {subprocess.py:93} INFO - During handling of the above exception, another exception occurred:
[2024-10-02T02:11:44.106+0000] {subprocess.py:93} INFO - 
[2024-10-02T02:11:44.106+0000] {subprocess.py:93} INFO - Traceback (most recent call last):
[2024-10-02T02:11:44.106+0000] {subprocess.py:93} INFO -   File "/home/***/.local/lib/python3.12/site-packages/requests/adapters.py", line 486, in send
[2024-10-02T02:11:44.106+0000] {subprocess.py:93} INFO -     resp = conn.urlopen(
[2024-10-02T02:11:44.106+0000] {subprocess.py:93} INFO -            ^^^^^^^^^^^^^
[2024-10-02T02:11:44.106+0000] {subprocess.py:93} INFO -   File "/home/***/.local/lib/python3.12/site-packages/urllib3/connectionpool.py", line 799, in urlopen
[2024-10-02T02:11:44.106+0000] {subprocess.py:93} INFO -     retries = retries.increment(
[2024-10-02T02:11:44.107+0000] {subprocess.py:93} INFO -               ^^^^^^^^^^^^^^^^^^
[2024-10-02T02:11:44.107+0000] {subprocess.py:93} INFO -   File "/home/***/.local/lib/python3.12/site-packages/urllib3/util/retry.py", line 592, in increment
[2024-10-02T02:11:44.107+0000] {subprocess.py:93} INFO -     raise MaxRetryError(_pool, url, error or ResponseError(cause))
[2024-10-02T02:11:44.107+0000] {subprocess.py:93} INFO - urllib3.exceptions.MaxRetryError: HTTPSConnectionPool(host='www.planecrashinfo.com', port=443): Max retries exceeded with url: /1920/1920-25.htm (Caused by NewConnectionError('<urllib3.connection.HTTPSConnection object at 0xffffba0e1460>: Failed to establish a new connection: [Errno 111] Connection refused'))
[2024-10-02T02:11:44.107+0000] {subprocess.py:93} INFO - 
[2024-10-02T02:11:44.107+0000] {subprocess.py:93} INFO - During handling of the above exception, another exception occurred:
[2024-10-02T02:11:44.107+0000] {subprocess.py:93} INFO - 
[2024-10-02T02:11:44.108+0000] {subprocess.py:93} INFO - Traceback (most recent call last):
[2024-10-02T02:11:44.108+0000] {subprocess.py:93} INFO -   File "/opt/***/tasks/flightDataWebScrape.py", line 91, in <module>
[2024-10-02T02:11:44.108+0000] {subprocess.py:93} INFO -     main()
[2024-10-02T02:11:44.108+0000] {subprocess.py:93} INFO -     ^^^^^^
[2024-10-02T02:11:44.108+0000] {subprocess.py:93} INFO -   File "/opt/***/tasks/flightDataWebScrape.py", line 37, in main
[2024-10-02T02:11:44.108+0000] {subprocess.py:93} INFO -     r = requests.get(url + str(year) + s + end2)
[2024-10-02T02:11:44.108+0000] {subprocess.py:93} INFO -         ^^^^^^^^^^^^^^^^^^^^^^^^^^^^^^^^^^^^^^^^
[2024-10-02T02:11:44.109+0000] {subprocess.py:93} INFO -   File "/home/***/.local/lib/python3.12/site-packages/requests/api.py", line 73, in get
[2024-10-02T02:11:44.109+0000] {subprocess.py:93} INFO -     return request("get", url, params=params, **kwargs)
[2024-10-02T02:11:44.109+0000] {subprocess.py:93} INFO -            ^^^^^^^^^^^^^^^^^^^^^^^^^^^^^^^^^^^^^^^^^^^^
[2024-10-02T02:11:44.109+0000] {subprocess.py:93} INFO -   File "/home/***/.local/lib/python3.12/site-packages/requests/api.py", line 59, in request
[2024-10-02T02:11:44.109+0000] {subprocess.py:93} INFO -     return session.request(method=method, url=url, **kwargs)
[2024-10-02T02:11:44.109+0000] {subprocess.py:93} INFO -            ^^^^^^^^^^^^^^^^^^^^^^^^^^^^^^^^^^^^^^^^^^^^^^^^^
[2024-10-02T02:11:44.109+0000] {subprocess.py:93} INFO -   File "/home/***/.local/lib/python3.12/site-packages/requests/sessions.py", line 589, in request
[2024-10-02T02:11:44.109+0000] {subprocess.py:93} INFO -     resp = self.send(prep, **send_kwargs)
[2024-10-02T02:11:44.109+0000] {subprocess.py:93} INFO -            ^^^^^^^^^^^^^^^^^^^^^^^^^^^^^^
[2024-10-02T02:11:44.110+0000] {subprocess.py:93} INFO -   File "/home/***/.local/lib/python3.12/site-packages/requests/sessions.py", line 703, in send
[2024-10-02T02:11:44.110+0000] {subprocess.py:93} INFO -     r = adapter.send(request, **kwargs)
[2024-10-02T02:11:44.110+0000] {subprocess.py:93} INFO -         ^^^^^^^^^^^^^^^^^^^^^^^^^^^^^^^
[2024-10-02T02:11:44.110+0000] {subprocess.py:93} INFO -   File "/home/***/.local/lib/python3.12/site-packages/requests/adapters.py", line 519, in send
[2024-10-02T02:11:44.110+0000] {subprocess.py:93} INFO -     raise ConnectionError(e, request=request)
[2024-10-02T02:11:44.110+0000] {subprocess.py:93} INFO - requests.exceptions.ConnectionError: HTTPSConnectionPool(host='www.planecrashinfo.com', port=443): Max retries exceeded with url: /1920/1920-25.htm (Caused by NewConnectionError('<urllib3.connection.HTTPSConnection object at 0xffffba0e1460>: Failed to establish a new connection: [Errno 111] Connection refused'))
[2024-10-02T02:11:44.146+0000] {subprocess.py:97} INFO - Command exited with return code 1
[2024-10-02T02:11:44.147+0000] {taskinstance.py:441} INFO - ::group::Post task execution logs
[2024-10-02T02:11:44.154+0000] {taskinstance.py:2890} ERROR - Task failed with exception
Traceback (most recent call last):
  File "/home/airflow/.local/lib/python3.12/site-packages/airflow/models/taskinstance.py", line 465, in _execute_task
    result = _execute_callable(context=context, **execute_callable_kwargs)
             ^^^^^^^^^^^^^^^^^^^^^^^^^^^^^^^^^^^^^^^^^^^^^^^^^^^^^^^^^^^^^
  File "/home/airflow/.local/lib/python3.12/site-packages/airflow/models/taskinstance.py", line 432, in _execute_callable
    return execute_callable(context=context, **execute_callable_kwargs)
           ^^^^^^^^^^^^^^^^^^^^^^^^^^^^^^^^^^^^^^^^^^^^^^^^^^^^^^^^^^^^
  File "/home/airflow/.local/lib/python3.12/site-packages/airflow/models/baseoperator.py", line 400, in wrapper
    return func(self, *args, **kwargs)
           ^^^^^^^^^^^^^^^^^^^^^^^^^^^
  File "/home/airflow/.local/lib/python3.12/site-packages/airflow/operators/bash.py", line 243, in execute
    raise AirflowException(
airflow.exceptions.AirflowException: Bash command failed. The command returned a non-zero exit code 1.
[2024-10-02T02:11:44.160+0000] {taskinstance.py:1205} INFO - Marking task as UP_FOR_RETRY. dag_id=AirCrashInvestigation_pipeline, task_id=scrape_LoadS3, execution_date=20240923T000000, start_date=20241002T020933, end_date=20241002T021144
[2024-10-02T02:11:44.169+0000] {standard_task_runner.py:110} ERROR - Failed to execute job 3 for task scrape_LoadS3 (Bash command failed. The command returned a non-zero exit code 1.; 77)
[2024-10-02T02:11:44.200+0000] {local_task_job_runner.py:240} INFO - Task exited with return code 1
[2024-10-02T02:11:44.213+0000] {taskinstance.py:3482} INFO - 0 downstream tasks scheduled from follow-on schedule check
[2024-10-02T02:11:44.215+0000] {local_task_job_runner.py:222} INFO - ::endgroup::
