[2024-09-25T21:35:41.461+0000] {local_task_job_runner.py:123} INFO - ::group::Pre task execution logs
[2024-09-25T21:35:41.471+0000] {taskinstance.py:2612} INFO - Dependencies all met for dep_context=non-requeueable deps ti=<TaskInstance: AirCrashInvestigation_pipeline.loadRedshift manual__2024-09-25T21:33:39.756279+00:00 [queued]>
[2024-09-25T21:35:41.475+0000] {taskinstance.py:2612} INFO - Dependencies all met for dep_context=requeueable deps ti=<TaskInstance: AirCrashInvestigation_pipeline.loadRedshift manual__2024-09-25T21:33:39.756279+00:00 [queued]>
[2024-09-25T21:35:41.475+0000] {taskinstance.py:2865} INFO - Starting attempt 2 of 2
[2024-09-25T21:35:41.488+0000] {taskinstance.py:2888} INFO - Executing <Task(BashOperator): loadRedshift> on 2024-09-25 21:33:39.756279+00:00
[2024-09-25T21:35:41.497+0000] {standard_task_runner.py:104} INFO - Running: ['***', 'tasks', 'run', 'AirCrashInvestigation_pipeline', 'loadRedshift', 'manual__2024-09-25T21:33:39.756279+00:00', '--job-id', '20', '--raw', '--subdir', 'DAGS_FOLDER/main_dag.py', '--cfg-path', '/tmp/tmp9wfa2nyv']
[2024-09-25T21:35:41.502+0000] {standard_task_runner.py:105} INFO - Job 20: Subtask loadRedshift
[2024-09-25T21:35:41.511+0000] {logging_mixin.py:190} WARNING - /home/***/.local/lib/python3.12/site-packages/***/task/task_runner/standard_task_runner.py:70 DeprecationWarning: This process (pid=313) is multi-threaded, use of fork() may lead to deadlocks in the child.
[2024-09-25T21:35:41.515+0000] {standard_task_runner.py:72} INFO - Started process 317 to run task
[2024-09-25T21:35:41.534+0000] {task_command.py:467} INFO - Running <TaskInstance: AirCrashInvestigation_pipeline.loadRedshift manual__2024-09-25T21:33:39.756279+00:00 [running]> on host fa5d07744004
[2024-09-25T21:35:41.588+0000] {taskinstance.py:3131} INFO - Exporting env vars: AIRFLOW_CTX_DAG_OWNER='***' AIRFLOW_CTX_DAG_ID='AirCrashInvestigation_pipeline' AIRFLOW_CTX_TASK_ID='loadRedshift' AIRFLOW_CTX_EXECUTION_DATE='2024-09-25T21:33:39.756279+00:00' AIRFLOW_CTX_TRY_NUMBER='2' AIRFLOW_CTX_DAG_RUN_ID='manual__2024-09-25T21:33:39.756279+00:00'
[2024-09-25T21:35:41.588+0000] {taskinstance.py:731} INFO - ::endgroup::
[2024-09-25T21:35:41.606+0000] {subprocess.py:63} INFO - Tmp dir root location: /tmp
[2024-09-25T21:35:41.608+0000] {subprocess.py:75} INFO - Running command: ['/usr/bin/bash', '-c', 'python3 opt/***/tasks/loadRedshift.py']
[2024-09-25T21:35:41.614+0000] {subprocess.py:86} INFO - Output:
[2024-09-25T21:35:41.656+0000] {subprocess.py:93} INFO - python3: can't open file '/tmp/***tmpinxa2_4_/opt/***/tasks/loadRedshift.py': [Errno 2] No such file or directory
[2024-09-25T21:35:41.658+0000] {subprocess.py:97} INFO - Command exited with return code 2
[2024-09-25T21:35:41.666+0000] {taskinstance.py:3310} ERROR - Task failed with exception
Traceback (most recent call last):
  File "/home/airflow/.local/lib/python3.12/site-packages/airflow/models/taskinstance.py", line 767, in _execute_task
    result = _execute_callable(context=context, **execute_callable_kwargs)
             ^^^^^^^^^^^^^^^^^^^^^^^^^^^^^^^^^^^^^^^^^^^^^^^^^^^^^^^^^^^^^
  File "/home/airflow/.local/lib/python3.12/site-packages/airflow/models/taskinstance.py", line 733, in _execute_callable
    return ExecutionCallableRunner(
           ^^^^^^^^^^^^^^^^^^^^^^^^
  File "/home/airflow/.local/lib/python3.12/site-packages/airflow/utils/operator_helpers.py", line 252, in run
    return self.func(*args, **kwargs)
           ^^^^^^^^^^^^^^^^^^^^^^^^^^
  File "/home/airflow/.local/lib/python3.12/site-packages/airflow/models/baseoperator.py", line 406, in wrapper
    return func(self, *args, **kwargs)
           ^^^^^^^^^^^^^^^^^^^^^^^^^^^
  File "/home/airflow/.local/lib/python3.12/site-packages/airflow/operators/bash.py", line 249, in execute
    raise AirflowException(
airflow.exceptions.AirflowException: Bash command failed. The command returned a non-zero exit code 2.
[2024-09-25T21:35:41.668+0000] {taskinstance.py:1225} INFO - Marking task as FAILED. dag_id=AirCrashInvestigation_pipeline, task_id=loadRedshift, run_id=manual__2024-09-25T21:33:39.756279+00:00, execution_date=20240925T213339, start_date=20240925T213541, end_date=20240925T213541
[2024-09-25T21:35:41.674+0000] {taskinstance.py:340} INFO - ::group::Post task execution logs
[2024-09-25T21:35:41.675+0000] {standard_task_runner.py:124} ERROR - Failed to execute job 20 for task loadRedshift (Bash command failed. The command returned a non-zero exit code 2.; 317)
Traceback (most recent call last):
  File "/home/airflow/.local/lib/python3.12/site-packages/airflow/task/task_runner/standard_task_runner.py", line 117, in _start_by_fork
    ret = args.func(args, dag=self.dag)
          ^^^^^^^^^^^^^^^^^^^^^^^^^^^^^
  File "/home/airflow/.local/lib/python3.12/site-packages/airflow/cli/cli_config.py", line 49, in command
    return func(*args, **kwargs)
           ^^^^^^^^^^^^^^^^^^^^^
  File "/home/airflow/.local/lib/python3.12/site-packages/airflow/utils/cli.py", line 115, in wrapper
    return f(*args, **kwargs)
           ^^^^^^^^^^^^^^^^^^
  File "/home/airflow/.local/lib/python3.12/site-packages/airflow/cli/commands/task_command.py", line 483, in task_run
    task_return_code = _run_task_by_selected_method(args, _dag, ti)
                       ^^^^^^^^^^^^^^^^^^^^^^^^^^^^^^^^^^^^^^^^^^^^
  File "/home/airflow/.local/lib/python3.12/site-packages/airflow/cli/commands/task_command.py", line 256, in _run_task_by_selected_method
    return _run_raw_task(args, ti)
           ^^^^^^^^^^^^^^^^^^^^^^^
  File "/home/airflow/.local/lib/python3.12/site-packages/airflow/cli/commands/task_command.py", line 341, in _run_raw_task
    return ti._run_raw_task(
           ^^^^^^^^^^^^^^^^^
  File "/home/airflow/.local/lib/python3.12/site-packages/airflow/utils/session.py", line 97, in wrapper
    return func(*args, session=session, **kwargs)
           ^^^^^^^^^^^^^^^^^^^^^^^^^^^^^^^^^^^^^^
  File "/home/airflow/.local/lib/python3.12/site-packages/airflow/models/taskinstance.py", line 3004, in _run_raw_task
    return _run_raw_task(
           ^^^^^^^^^^^^^^
  File "/home/airflow/.local/lib/python3.12/site-packages/airflow/models/taskinstance.py", line 273, in _run_raw_task
    TaskInstance._execute_task_with_callbacks(
  File "/home/airflow/.local/lib/python3.12/site-packages/airflow/models/taskinstance.py", line 3158, in _execute_task_with_callbacks
    result = self._execute_task(context, task_orig)
             ^^^^^^^^^^^^^^^^^^^^^^^^^^^^^^^^^^^^^^
  File "/home/airflow/.local/lib/python3.12/site-packages/airflow/models/taskinstance.py", line 3182, in _execute_task
    return _execute_task(self, context, task_orig)
           ^^^^^^^^^^^^^^^^^^^^^^^^^^^^^^^^^^^^^^^
  File "/home/airflow/.local/lib/python3.12/site-packages/airflow/models/taskinstance.py", line 767, in _execute_task
    result = _execute_callable(context=context, **execute_callable_kwargs)
             ^^^^^^^^^^^^^^^^^^^^^^^^^^^^^^^^^^^^^^^^^^^^^^^^^^^^^^^^^^^^^
  File "/home/airflow/.local/lib/python3.12/site-packages/airflow/models/taskinstance.py", line 733, in _execute_callable
    return ExecutionCallableRunner(
           ^^^^^^^^^^^^^^^^^^^^^^^^
  File "/home/airflow/.local/lib/python3.12/site-packages/airflow/utils/operator_helpers.py", line 252, in run
    return self.func(*args, **kwargs)
           ^^^^^^^^^^^^^^^^^^^^^^^^^^
  File "/home/airflow/.local/lib/python3.12/site-packages/airflow/models/baseoperator.py", line 406, in wrapper
    return func(self, *args, **kwargs)
           ^^^^^^^^^^^^^^^^^^^^^^^^^^^
  File "/home/airflow/.local/lib/python3.12/site-packages/airflow/operators/bash.py", line 249, in execute
    raise AirflowException(
airflow.exceptions.AirflowException: Bash command failed. The command returned a non-zero exit code 2.
[2024-09-25T21:35:41.700+0000] {local_task_job_runner.py:266} INFO - Task exited with return code 1
[2024-09-25T21:35:41.712+0000] {taskinstance.py:3900} INFO - 0 downstream tasks scheduled from follow-on schedule check
[2024-09-25T21:35:41.714+0000] {local_task_job_runner.py:245} INFO - ::endgroup::
